Workbook

Sheet Tong quan
A1: PHÂN TÍCH CHỨC NĂNG "FIXERROR" – TỰ SỬA DỮ LIỆU XML TRƯỚC KHI GỬI CỔNG BHXH
A3: Nguồn phân tích | B3: Mã nguồn C# namespace BVBMHIS.BHYT.HIS4750.FIXERROR (16 tệp: FIX_XML1…15, REF_DATA) – hệ thống khác, không phải Tiền giám định.
A4: Cơ chế | B4: Ngay trước khi tạo XML gửi cổng, chương trình tự sửa giá trị trong BẢN XML. Dữ liệu gốc trên HIS KHÔNG được sửa.
A5: Hệ quả chung | B5: Dữ liệu trên cổng BHXH ≠ dữ liệu trên HIS / bệnh án / giấy tờ đã in cho người bệnh. Khi BHXH giám định, đối chiếu hồ sơ giấy hoặc hậu kiểm, bệnh viện không giải trình được vì "nguồn" và "bản gửi" khác nhau. Lỗi gốc không bao giờ được sửa vì đã bị che trên cổng.
A6: Nguyên tắc đúng | B6: Sửa tại nguồn (HIS) rồi xuất lại; công cụ kiểm tra chỉ được CẢNH BÁO và chặn gửi, không tự sửa nội dung chuyên môn.
A7: Chưa xác định | B7: Giá trị các hằng BHYTConfig.BSKhongDienTT, DuocChuaNhapTT, PVTChuaNhapTT, MA_TTDV… không có trong mã nguồn được cung cấp – ghi là "<chuỗi cấu hình>".
A8: Không sửa gì | B8: XML6 (HIV), XML10 (nghỉ dưỡng thai), XML12 (giám định y khoa), XML15 (điều trị lao): hàm có nhưng để trống.
A11: THỐNG KÊ QUY TẮC TỰ SỬA
A12: Bảng XML | B12: Nghiêm trọng | C12: Cao | D12: Trung bình | E12: Tổng
A13: XML1 | B13: =COUNTIFS('Chi tiet quy tac'!$B$2:$B$60,$A13,'Chi tiet quy tac'!$J$2:$J$60,B$12) | C13: =COUNTIFS('Chi tiet quy tac'!$B$2:$B$60,$A13,'Chi tiet quy tac'!$J$2:$J$60,C$12) | D13: =COUNTIFS('Chi tiet quy tac'!$B$2:$B$60,$A13,'Chi tiet quy tac'!$J$2:$J$60,D$12) | E13: =SUM(B13:D13)
A14: XML2 | B14: =COUNTIFS('Chi tiet quy tac'!$B$2:$B$60,$A14,'Chi tiet quy tac'!$J$2:$J$60,B$12) | C14: =COUNTIFS('Chi tiet quy tac'!$B$2:$B$60,$A14,'Chi tiet quy tac'!$J$2:$J$60,C$12) | D14: =COUNTIFS('Chi tiet quy tac'!$B$2:$B$60,$A14,'Chi tiet quy tac'!$J$2:$J$60,D$12) | E14: =SUM(B14:D14)
A15: XML3 | B15: =COUNTIFS('Chi tiet quy tac'!$B$2:$B$60,$A15,'Chi tiet quy tac'!$J$2:$J$60,B$12) | C15: =COUNTIFS('Chi tiet quy tac'!$B$2:$B$60,$A15,'Chi tiet quy tac'!$J$2:$J$60,C$12) | D15: =COUNTIFS('Chi tiet quy tac'!$B$2:$B$60,$A15,'Chi tiet quy tac'!$J$2:$J$60,D$12) | E15: =SUM(B15:D15)
A16: XML4 | B16: =COUNTIFS('Chi tiet quy tac'!$B$2:$B$60,$A16,'Chi tiet quy tac'!$J$2:$J$60,B$12) | C16: =COUNTIFS('Chi tiet quy tac'!$B$2:$B$60,$A16,'Chi tiet quy tac'!$J$2:$J$60,C$12) | D16: =COUNTIFS('Chi tiet quy tac'!$B$2:$B$60,$A16,'Chi tiet quy tac'!$J$2:$J$60,D$12) | E16: =SUM(B16:D16)
A17: XML5 | B17: =COUNTIFS('Chi tiet quy tac'!$B$2:$B$60,$A17,'Chi tiet quy tac'!$J$2:$J$60,B$12) | C17: =COUNTIFS('Chi tiet quy tac'!$B$2:$B$60,$A17,'Chi tiet quy tac'!$J$2:$J$60,C$12) | D17: =COUNTIFS('Chi tiet quy tac'!$B$2:$B$60,$A17,'Chi tiet quy tac'!$J$2:$J$60,D$12) | E17: =SUM(B17:D17)
A18: XML7 | B18: =COUNTIFS('Chi tiet quy tac'!$B$2:$B$60,$A18,'Chi tiet quy tac'!$J$2:$J$60,B$12) | C18: =COUNTIFS('Chi tiet quy tac'!$B$2:$B$60,$A18,'Chi tiet quy tac'!$J$2:$J$60,C$12) | D18: =COUNTIFS('Chi tiet quy tac'!$B$2:$B$60,$A18,'Chi tiet quy tac'!$J$2:$J$60,D$12) | E18: =SUM(B18:D18)
A19: XML8 | B19: =COUNTIFS('Chi tiet quy tac'!$B$2:$B$60,$A19,'Chi tiet quy tac'!$J$2:$J$60,B$12) | C19: =COUNTIFS('Chi tiet quy tac'!$B$2:$B$60,$A19,'Chi tiet quy tac'!$J$2:$J$60,C$12) | D19: =COUNTIFS('Chi tiet quy tac'!$B$2:$B$60,$A19,'Chi tiet quy tac'!$J$2:$J$60,D$12) | E19: =SUM(B19:D19)
A20: XML9 | B20: =COUNTIFS('Chi tiet quy tac'!$B$2:$B$60,$A20,'Chi tiet quy tac'!$J$2:$J$60,B$12) | C20: =COUNTIFS('Chi tiet quy tac'!$B$2:$B$60,$A20,'Chi tiet quy tac'!$J$2:$J$60,C$12) | D20: =COUNTIFS('Chi tiet quy tac'!$B$2:$B$60,$A20,'Chi tiet quy tac'!$J$2:$J$60,D$12) | E20: =SUM(B20:D20)
A21: XML11 | B21: =COUNTIFS('Chi tiet quy tac'!$B$2:$B$60,$A21,'Chi tiet quy tac'!$J$2:$J$60,B$12) | C21: =COUNTIFS('Chi tiet quy tac'!$B$2:$B$60,$A21,'Chi tiet quy tac'!$J$2:$J$60,C$12) | D21: =COUNTIFS('Chi tiet quy tac'!$B$2:$B$60,$A21,'Chi tiet quy tac'!$J$2:$J$60,D$12) | E21: =SUM(B21:D21)
A22: XML13 | B22: =COUNTIFS('Chi tiet quy tac'!$B$2:$B$60,$A22,'Chi tiet quy tac'!$J$2:$J$60,B$12) | C22: =COUNTIFS('Chi tiet quy tac'!$B$2:$B$60,$A22,'Chi tiet quy tac'!$J$2:$J$60,C$12) | D22: =COUNTIFS('Chi tiet quy tac'!$B$2:$B$60,$A22,'Chi tiet quy tac'!$J$2:$J$60,D$12) | E22: =SUM(B22:D22)
A23: XML14 | B23: =COUNTIFS('Chi tiet quy tac'!$B$2:$B$60,$A23,'Chi tiet quy tac'!$J$2:$J$60,B$12) | C23: =COUNTIFS('Chi tiet quy tac'!$B$2:$B$60,$A23,'Chi tiet quy tac'!$J$2:$J$60,C$12) | D23: =COUNTIFS('Chi tiet quy tac'!$B$2:$B$60,$A23,'Chi tiet quy tac'!$J$2:$J$60,D$12) | E23: =SUM(B23:D23)
A24: Tổng cộng | B24: =SUM(B13:B23) | C24: =SUM(C13:C23) | D24: =SUM(D13:D23) | E24: =SUM(E13:E23)
A26: Mức độ
A27: Nghiêm trọng | B27: Bịa/đổi dữ liệu chuyên môn hoặc người chịu trách nhiệm; ảnh hưởng quyền lợi, thanh toán, pháp lý.
A28: Cao | B28: Thay đổi nội dung so với HIS, dữ liệu giả không có giá trị.
A29: Trung bình | B29: Chuẩn hoá định dạng / cắt chuỗi / lệch nhỏ.

Sheet Chi tiet quy tac
A1: STT | B1: Bảng | C1: Tên bảng | D1: Trường bị sửa | E1: Khi nào bị sửa | F1: Công cụ tự sửa thế nào | G1: Ví dụ (HIS → Cổng) | H1: Hậu quả lệch HIS – cổng | I1: Loại can thiệp | J1: Mức độ | K1: Lỗi lập trình kèm theo | L1: Cách xử lý đúng | M1: Vị trí mã nguồn
A2: 1 | B2: XML1 | C2: XML1 – Tổng hợp KCB | D2: MA_KHUVUC | E2: Giá trị không chứa chữ "K" | F2: Xoá thành rỗng | G2: HIS: "1" → Cổng: "" | H2: Mất thông tin khu vực (K1/K2/K3) – liên quan quyền lợi hưởng; HIS vẫn lưu giá trị cũ. | I2: Xoá dữ liệu | J2: Trung bình | L2: Khoa/người nhập sửa trên HIS rồi xuất lại; công cụ chỉ được CẢNH BÁO, không tự sửa. | M2: FIX_XML1.cs:19
A3: 2 | B3: XML1 | C3: XML1 – Tổng hợp KCB | D3: MATINH_CU_TRU | E3: Rỗng | F3: Gán cứng "01" (Hà Nội) | G3: HIS: "" → Cổng: "01" | H3: Mọi BN thiếu tỉnh đều thành cư trú Hà Nội trên cổng; thống kê/đối chiếu nơi cư trú sai. | I3: Bịa giá trị | J3: Cao | L3: Khoa/người nhập sửa trên HIS rồi xuất lại; công cụ chỉ được CẢNH BÁO, không tự sửa. | M3: FIX_XML1.cs:23
A4: 3 | B4: XML1 | C4: XML1 – Tổng hợp KCB | D4: MATINH_CU_TRU | E4: Độ dài ≥ 3 ký tự | F4: Lấy ký tự thứ 2–3 (Substring(1,2)) | G4: HIS: "001" → Cổng: "01" | H4: Đổi mã so với HIS; nếu mã 3 ký tự không bắt đầu bằng 0 sẽ ra tỉnh khác. | I4: Thay mã | J4: Trung bình | L4: Chuẩn hoá danh mục tỉnh trên HIS. | M4: FIX_XML1.cs:32
A5: 4 | B5: XML1 | C5: XML1 – Tổng hợp KCB | D5: DIA_CHI | E5: Rỗng | F5: Ghép ".,<xã>,<huyện>,<tỉnh>" từ danh mục ĐVHC; không khớp thì ra ".,,," | G5: HIS: "" → Cổng: ".,Phường X,Quận Y,Hà Nội" hoặc ".,,," | H5: Địa chỉ trên cổng không do người nhập khai; có thể ghép từ tỉnh "01" vừa bịa ở dòng trên. | I5: Bịa giá trị | J5: Cao | L5: Khoa/người nhập sửa trên HIS rồi xuất lại; công cụ chỉ được CẢNH BÁO, không tự sửa. | M5: FIX_XML1.cs:50
A6: 5 | B6: XML1 | C6: XML1 – Tổng hợp KCB | D6: LY_DO_VV | E6: Rỗng | F6: Gán chữ "LY_DO_VV" | G6: HIS: "" → Cổng: "LY_DO_VV" | H6: Lý do vào viện trên cổng là chữ vô nghĩa; HIS trống. | I6: Bịa giá trị | J6: Cao | L6: Khoa/người nhập sửa trên HIS rồi xuất lại; công cụ chỉ được CẢNH BÁO, không tự sửa. | M6: FIX_XML1.cs:68
A7: 6 | B7: XML1 | C7: XML1 – Tổng hợp KCB | D7: LY_DO_VNT | E7: MA_LY_DO_VNT rỗng | F7: Ghi đè LY_DO_VNT bằng 5 ký tự đầu của MA_BENH_CHINH | G7: HIS: "Đau bụng cấp" → Cổng: "K35.8" | H7: Ghi đè cả khi LY_DO_VNT đã có nội dung bác sĩ nhập → mất nội dung thật, thay bằng mã bệnh. | I7: Ghi đè dữ liệu | J7: Cao | K7: Kiểm tra MA_LY_DO_VNT nhưng ghi đè LY_DO_VNT, không xét LY_DO_VNT đã có giá trị hay chưa. | L7: Khoa/người nhập sửa trên HIS rồi xuất lại; công cụ chỉ được CẢNH BÁO, không tự sửa. | M7: FIX_XML1.cs:72
A8: 7 | B8: XML1 | C8: XML1 – Tổng hợp KCB | D8: LY_DO_VNT | E8: Vẫn rỗng sau bước trên | F8: Gán chữ "LY_DO_VNT" | G8: HIS: "" → Cổng: "LY_DO_VNT" | H8: Dữ liệu giả. | I8: Bịa giá trị | J8: Cao | L8: Khoa/người nhập sửa trên HIS rồi xuất lại; công cụ chỉ được CẢNH BÁO, không tự sửa. | M8: FIX_XML1.cs:83
A9: 8 | B9: XML1 | C9: XML1 – Tổng hợp KCB | D9: MA_NGHE_NGHIEP | E9: Rỗng | F9: Gán "00" | G9: HIS: "" → Cổng: "00" | H9: Cổng nhận mã nghề mặc định, HIS trống. | I9: Bịa giá trị | J9: Trung bình | L9: Khoa/người nhập sửa trên HIS rồi xuất lại; công cụ chỉ được CẢNH BÁO, không tự sửa. | M9: FIX_XML1.cs:88
A10: 9 | B10: XML1 | C10: XML1 – Tổng hợp KCB | D10: CAN_NANG | E10: Rỗng | F10: Bịa cân nặng theo tuổi: ≤1 tuổi = 5 kg; 2 tuổi = 13; 3 = 14 … 17 tuổi = 40; ≥18 tuổi = 45 kg | G10: BN 70 tuổi, HIS: "" → Cổng: "45" | H10: Chỉ số lâm sàng bịa đặt. Cổng giám định liều thuốc/kg, truyền dịch… dựa trên số giả → kết quả giám định sai, HIS không có số này. | I10: Bịa giá trị | J10: Nghiêm trọng | K10: Tuổi = năm hiện tại − năm sinh (không theo ngày vào viện). Không đọc được ngày sinh → năm sinh = 0 → luôn 45 kg. | L10: Khoa/người nhập sửa trên HIS rồi xuất lại; công cụ chỉ được CẢNH BÁO, không tự sửa. | M10: FIX_XML1.cs:111
A11: 10 | B11: XML1 | C11: XML1 – Tổng hợp KCB | D11: CAN_NANG | E11: > 1000 | F11: Chia 1000 (giả định nhập gam) | G11: HIS: "3200" → Cổng: "3.20" | H11: Đổi số liệu so với HIS. | I11: Đổi đơn vị | J11: Trung bình | L11: Sửa tại nguồn nhập liệu. | M11: FIX_XML1.cs:181
A12: 11 | B12: XML1 | C12: XML1 – Tổng hợp KCB | D12: CAN_NANG_CON | E12: Có giá trị | F12: Làm tròn thành số nguyên | G12: HIS: "3250.6" → Cổng: "3251" | H12: Lệch nhỏ. | I12: Định dạng | J12: Trung bình | M12: FIX_XML1.cs:195
A13: 12 | B13: XML1 | C13: XML1 – Tổng hợp KCB | D13: MA_BENH_CHINH, MA_BENH_KT | E13: Luôn chạy | F13: Thay chuỗi con 6 mã: U62.152→M15; A91→A90; I84→K64; N18.0→N18; U58.091→I10; U55.561→G51 | G13: HIS: "A91" (SXH Dengue) → Cổng: "A90" (Sốt Dengue) | H13: ĐỔI CHẨN ĐOÁN mà bác sĩ không biết. Chẩn đoán trên HIS/bệnh án ≠ chẩn đoán trên cổng → không đối chiếu được, căn cứ chỉ định DVKT/thuốc có thể không còn phù hợp. | I13: Thay mã ICD | J13: Nghiêm trọng | K13: Dùng Replace chuỗi con, không so khớp nguyên mã → có thể "ăn" cả mã chứa chuỗi đó. | L13: Bác sĩ chọn đúng mã ICD trên HIS; cập nhật danh mục ICD trên HIS. | M13: FIX_XML1.cs:205
A14: 13 | B14: XML1 | C14: XML1 – Tổng hợp KCB | D14: MA_BENH_CHINH, MA_BENH_KT | E14: Mã nằm trong bảng 27 mã "TT mới áp dụng 1.7.2026" | F14: Đổi sang mã mới (xem sheet "Ma ICD bi doi") | G14: HIS: "K35.9" → Cổng: "K35.8" | H14: HIS vẫn lưu mã cũ, cổng nhận mã mới → lệch vĩnh viễn; bệnh án điện tử/thống kê HIS khác dữ liệu thanh toán. | I14: Thay mã ICD | J14: Nghiêm trọng | L14: Cập nhật danh mục ICD trên HIS theo văn bản mới, khoá mã cũ; bác sĩ chọn lại mã. | M14: FIX_XML1.cs:220
A15: 14 | B15: XML1 | C15: XML1 – Tổng hợp KCB | D15: MA_BENH_KT | E15: Mã thuộc nhóm Z00–Z13 (khám, sàng lọc…) | F15: Loại bỏ khỏi chuỗi bệnh kèm theo (104 mã, xem sheet "Ma Z bi xoa") | G15: HIS: "E11;Z01.7" → Cổng: "E11" | H15: Mất chẩn đoán kèm theo trên cổng. XML3.MA_BENH không bị lọc → DVKT gắn mã Z không còn khớp chẩn đoán của XML1. | I15: Xoá dữ liệu | J15: Cao | L15: Quy định/hướng dẫn bác sĩ không ghi mã Z không phù hợp ngay trên HIS. | M15: FIX_XML1.cs:289
A16: 15 | B16: XML1 | C16: XML1 – Tổng hợp KCB | D16: MA_DOITUONG_KCB | E16: Rỗng | F16: Suy đoán: tỷ lệ T_TONGCHI_BH/T_TONGCHI_BV ≤ 40% → "3"; khoa K02.1/K02.2 → "2"; còn lại → "1" | G16: HIS: "" → Cổng: "1" | H16: Đối tượng KCB quyết định tuyến/mức hưởng BHYT; tự đoán theo tỷ lệ tiền là suy diễn, có thể sai quyền lợi. | I16: Suy đoán giá trị | J16: Nghiêm trọng | K16: So sánh yyyyMM (6 số, VD 202510) với 20240702 (8 số) → điều kiện "trước 02/07/2024" LUÔN ĐÚNG, áp dụng cả hồ sơ mới. T_TONGCHI_BV = 0 → lỗi chia cho 0. | L16: Khoa/người nhập sửa trên HIS rồi xuất lại; công cụ chỉ được CẢNH BÁO, không tự sửa. | M16: FIX_XML1.cs:298
A17: 16 | B17: XML1 | C17: XML1 – Tổng hợp KCB | D17: PP_DIEU_TRI | E17: Rỗng / dài ≥ 1296 | F17: Rỗng → "PP_DIEU_TRI" + hằng BSKhongDienTT; dài → cắt 1296 ký tự + "..." | G17: HIS: "" → Cổng: "PP_DIEU_TRI<chuỗi cấu hình>" | H17: Dữ liệu giả hoặc bị cắt; HIS khác cổng. | I17: Bịa / cắt chuỗi | J17: Cao | L17: Khoa/người nhập sửa trên HIS rồi xuất lại; công cụ chỉ được CẢNH BÁO, không tự sửa. | M17: FIX_XML1.cs:330
A18: 17 | B18: XML1 | C18: XML1 – Tổng hợp KCB | D18: GIAY_CHUYEN_TUYEN | E18: MA_DOITUONG_KCB = 1.3 hoặc 1.5 và rỗng | F18: Gán số giấy giả "...../20../PCCSKBCB" | G18: HIS: "" → Cổng: "...../20../PCCSKBCB" | H18: Hồ sơ chuyển tuyến không có giấy vẫn được gửi như có giấy → hưởng quyền lợi đúng tuyến không có căn cứ; rủi ro xuất toán, trách nhiệm pháp lý. | I18: Bịa giá trị | J18: Nghiêm trọng | L18: Bắt buộc nhập số giấy chuyển tuyến trên HIS; thiếu thì không duyệt hồ sơ. | M18: FIX_XML1.cs:339
A19: 18 | B19: XML2 | C19: XML2 – Chi tiết thuốc | D19: MA_THUOC, TEN_THUOC | E19: Rỗng | F19: Gán hằng BHYTConfig.DuocChuaNhapTT | G19: HIS: "" → Cổng: "<chuỗi cấu hình>" | H19: Thuốc không có mã vẫn được gửi với mã giả. | I19: Bịa giá trị | J19: Cao | L19: Khoa Dược chuẩn hoá danh mục thuốc trên HIS. | M19: FIX_XML2.cs:22
A20: 19 | B20: XML2 | C20: XML2 – Chi tiết thuốc | D20: MA_THUOC | E20: =KTCGT120 hoặc KTCGT250 | F20: Đổi thành "9.4.KTNAT" | G20: HIS: "KTCGT120" → Cổng: "9.4.KTNAT" | H20: Mã thuốc trên cổng khác mã trên HIS/kho dược → không đối chiếu được xuất–nhập–tồn. | I20: Thay mã | J20: Cao | L20: Sửa mã trong danh mục thuốc HIS. | M20: FIX_XML2.cs:38
A21: 20 | B21: XML2 | C21: XML2 – Chi tiết thuốc | D21: SO_DANG_KY | E21: MA_THUOC rỗng và SO_DANG_KY rỗng | F21: Gán DuocChuaNhapTT | G21: — | H21: Không bao giờ chạy. | I21: Bịa giá trị | J21: Trung bình | K21: Code chết: MA_THUOC đã được gán ở bước trước nên điều kiện không bao giờ đúng. | M21: FIX_XML2.cs:40
A22: 21 | B22: XML2 | C22: XML2 – Chi tiết thuốc | D22: NGAY_YL | E22: NGAY_YL > NGAY_RA hoặc < NGAY_VAO | F22: Kéo NGAY_YL về đúng NGAY_RA / NGAY_VAO | G22: HIS: 202510151030 (sau ra viện) → Cổng: = NGAY_RA | H22: CHE GIẤU y lệnh ngoài thời gian điều trị – đúng loại lỗi cổng phải xuất toán. Thời gian y lệnh trên cổng ≠ HIS/bệnh án. | I22: Sửa thời gian | J22: Nghiêm trọng | L22: Rà soát hồ sơ, sửa thời gian y lệnh hoặc ngày vào/ra trên HIS cho đúng thực tế. | M22: FIX_XML2.cs:47, :78
A23: 22 | B23: XML2 | C23: XML2 – Chi tiết thuốc | D23: NGAY_TH_YL | E23: NGAY_YL > NGAY_TH_YL | F23: Gán NGAY_TH_YL = NGAY_YL | G23: HIS: TH 08:00, YL 09:00 → Cổng: TH 09:00 | H23: Thời gian thực hiện y lệnh bị bịa. | I23: Sửa thời gian | J23: Cao | K23: Sửa NGAY_TH_YL TRƯỚC khi kéo NGAY_YL lên NGAY_VAO → sau khi sửa vẫn có thể NGAY_YL > NGAY_TH_YL. | L23: Khoa/người nhập sửa trên HIS rồi xuất lại; công cụ chỉ được CẢNH BÁO, không tự sửa. | M23: FIX_XML2.cs:54
A24: 23 | B24: XML2 | C24: XML2 – Chi tiết thuốc | D24: MA_BAC_SI | E24: Có "CNTT" hoặc rỗng | F24: Bỏ "CNTT"; rỗng → gán mã CCHN TRƯỞNG KHOA theo MA_KHOA (xem sheet "Truong khoa gan thay") | G24: HIS: "" → Cổng: "0010527/BYT-CCHN" | H24: Người chỉ định trên cổng là trưởng khoa dù họ không chỉ định → sai trách nhiệm chuyên môn, pháp lý; HIS không có. | I24: Gán người khác | J24: Nghiêm trọng | K24: Khoa không có trong danh sách → vẫn rỗng. | L24: Bắt buộc ký/chọn bác sĩ chỉ định trên HIS. | M24: FIX_XML2.cs:83
A25: 24 | B25: XML3 | C25: XML3 – Chi tiết DVKT & VTYT | D25: MA_BENH | E25: Luôn chạy | F25: Thay chuỗi con 6 mã ICD như XML1 | G25: HIS: "A91" → Cổng: "A90" | H25: Đổi chẩn đoán gắn với DVKT. | I25: Thay mã ICD | J25: Nghiêm trọng | K25: Không áp dụng bảng 27 mã và lọc Z như XML1 → XML1 và XML3 lệch nhau. | L25: Như XML1. | M25: FIX_XML3.cs:22
A26: 25 | B26: XML3 | C26: XML3 – Chi tiết DVKT & VTYT | D26: MA_GIUONG | E26: Chứa H17A / H17B | F26: Đổi thành H017 | G26: HIS: "H17A" → Cổng: "H017" | H26: Mã giường trên cổng khác HIS; 2 giường khác nhau gộp thành 1 mã. | I26: Thay mã | J26: Cao | L26: Chuẩn hoá danh mục giường trên HIS. | M26: FIX_XML3.cs:28
A27: 26 | B27: XML3 | C27: XML3 – Chi tiết DVKT & VTYT | D27: MA_VAT_TU, TEN_VAT_TU (nhóm 10) | E27: Rỗng | F27: Gán hằng BHYTConfig.PVTChuaNhapTT | G27: HIS: "" → Cổng: "<chuỗi cấu hình>" | H27: Vật tư không mã vẫn gửi cổng. | I27: Bịa giá trị | J27: Cao | L27: Chuẩn hoá danh mục VTYT. | M27: FIX_XML3.cs:32
A28: 27 | B28: XML3 | C28: XML3 – Chi tiết DVKT & VTYT | D28: GOI_VTYT, MA_DICH_VU, TEN_DICH_VU (nhóm 10) | E28: GOI_VTYT từ G30 đến G99 | F28: Xoá cả 3 trường | G28: HIS: G35 / 01.0001.xxxx → Cổng: rỗng | H28: Mất liên kết vật tư với DVKT/gói → cổng không tính được trần gói, vật tư thành độc lập; HIS vẫn có liên kết. | I28: Xoá dữ liệu | J28: Nghiêm trọng | L28: Kiểm soát số gói trên HIS; báo lỗi thay vì xoá. | M28: FIX_XML3.cs:44
A29: 28 | B29: XML3 | C29: XML3 – Chi tiết DVKT & VTYT | D29: TAI_SU_DUNG (nhóm 10) | E29: =1 và DON_GIA_BH ≠ DON_GIA_BV | F29: Xoá cờ tái sử dụng | G29: HIS: "1" → Cổng: "" | H29: Vật tư tái sử dụng bị khai là dùng 1 lần → thanh toán sai. | I29: Xoá dữ liệu | J29: Nghiêm trọng | L29: Sửa giá/cờ tái sử dụng trên HIS. | M29: FIX_XML3.cs:56
A30: 29 | B30: XML3 | C30: XML3 – Chi tiết DVKT & VTYT | D30: MA_VAT_TU (DVKT y học hạt nhân) | E30: MA_DICH_VU thuộc 71 mã DVKT (19.xxxx, 12.036x) và MA_VAT_TU rỗng | F30: Gán CỨNG mã "40P.xx" (+ "40P.52") theo từng DVKT – xem sheet "Ma VT gan cung" | G30: HIS: "" → Cổng: "40P.16+40P.52" | H30: Khai vật tư/thuốc phóng xạ đã dùng mà không căn cứ thực tế sử dụng; HIS không ghi nhận. Nếu thực tế dùng loại khác hoặc không dùng → khai sai. | I30: Bịa giá trị | J30: Nghiêm trọng | L30: Khoa YHHN ghi nhận vật tư/thuốc thực dùng trên HIS. | M30: FIX_XML3.cs:62-208
A31: 30 | B31: XML3 | C31: XML3 – Chi tiết DVKT & VTYT | D31: NGAY_YL | E31: > NGAY_RA hoặc < NGAY_VAO | F31: Kéo về NGAY_RA / NGAY_VAO | G31: Như XML2 | H31: Che giấu chỉ định ngoài thời gian điều trị. | I31: Sửa thời gian | J31: Nghiêm trọng | L31: Như XML2. | M31: FIX_XML3.cs:210
A32: 31 | B32: XML3 | C32: XML3 – Chi tiết DVKT & VTYT | D32: MA_BAC_SI | E32: Có "CNTT" hoặc rỗng | F32: Bỏ "CNTT"; rỗng → CCHN trưởng khoa | G32: Như XML2 | H32: Sai người chỉ định. | I32: Gán người khác | J32: Nghiêm trọng | L32: Như XML2. | M32: FIX_XML3.cs:222
A33: 32 | B33: XML3 | C33: XML3 – Chi tiết DVKT & VTYT | D33: NGAY_KQ | E33: > (giờ xuất file − 3 phút) hoặc < NGAY_YL | F33: Gán = giờ xuất file − 3 phút, hoặc = NGAY_YL | G33: HIS: "" / sai → Cổng: thời điểm chạy công cụ | H33: Thời gian có kết quả là thời điểm máy xuất XML, không phải lúc có kết quả thật; mỗi lần xuất lại ra giá trị khác. | I33: Sửa thời gian | J33: Cao | L33: Khoa/người nhập sửa trên HIS rồi xuất lại; công cụ chỉ được CẢNH BÁO, không tự sửa. | M33: FIX_XML3.cs:224
A34: 33 | B34: XML3 | C34: XML3 – Chi tiết DVKT & VTYT | D34: NGAY_TH_YL | E34: > giờ xuất − 3 phút hoặc < NGAY_YL | F34: Gán = giờ xuất − 3 phút, hoặc = NGAY_YL | G34: Như trên | H34: Thời gian thực hiện bịa. | I34: Sửa thời gian | J34: Cao | L34: Khoa/người nhập sửa trên HIS rồi xuất lại; công cụ chỉ được CẢNH BÁO, không tự sửa. | M34: FIX_XML3.cs:248
A35: 34 | B35: XML3 | C35: XML3 – Chi tiết DVKT & VTYT | D35: PP_VO_CAM | E35: Không thuộc 1/2/3/4 | F35: Nhóm 8, 18 (PT/TT) → "4"; nhóm khác → rỗng | G35: HIS: "" → Cổng: "4" | H35: Phương pháp vô cảm không có trong biên bản PT/TT vẫn được khai; giá PT/TT phụ thuộc vô cảm. | I35: Bịa giá trị | J35: Nghiêm trọng | L35: Bắt buộc nhập PP vô cảm trong phiếu PT/TT trên HIS. | M35: FIX_XML3.cs:271
A36: 35 | B36: XML3 | C36: XML3 – Chi tiết DVKT & VTYT | D36: NGUOI_THUC_HIEN (nhóm 1,2,3,8,18) | E36: Rỗng | F36: Bỏ "CNTT"; DV khí máu 23.0103.1531 hoặc y lệnh trước 01/07/2024 → gán = MA_BAC_SI (người chỉ định); từ 01/07/2024 → "0000000000" | G36: HIS: "" → Cổng: "0000000000" hoặc = bác sĩ chỉ định | H36: Người thực hiện XN/CĐHA/PT bị bịa (chỉ định = thực hiện) hoặc mã giả toàn số 0. | I36: Gán người khác | J36: Nghiêm trọng | L36: Bắt buộc ghi người thực hiện trên HIS/LIS/PACS. | M36: FIX_XML3.cs:300
A37: 36 | B37: XML3 | C37: XML3 – Chi tiết DVKT & VTYT | D37: MA_BENH | E37: Nhiều hơn 13 mã | F37: Giữ 13 mã đầu, luôn thêm ";" cuối chuỗi | G37: HIS: 15 mã → Cổng: 13 mã + ";" | H37: Mất mã bệnh; chuỗi có dấu ";" thừa. | I37: Cắt chuỗi | J37: Trung bình | K37: Luôn nối ";" kể cả mã cuối. | M37: FIX_XML3.cs:330
A38: 37 | B38: XML4 | C38: XML4 – Chỉ số CLS | D38: GIA_TRI | E38: Dài ≥ 51 ký tự | F38: Cắt 47 ký tự + "..." | G38: HIS: kết quả đầy đủ → Cổng: bị cắt | H38: Kết quả xét nghiệm trên cổng bị cụt, có thể mất phần kết luận/đơn vị. | I38: Cắt chuỗi | J38: Cao | L38: Kết quả dài nên đưa vào KET_LUAN/MO_TA đúng trường. | M38: FIX_XML4.cs:25
A39: 38 | B39: XML4 | C39: XML4 – Chỉ số CLS | D39: NGAY_KQ | E39: Rỗng hoặc > giờ xuất − 3 phút | F39: Gán = giờ xuất − 3 phút | G39: HIS: "" → Cổng: thời điểm chạy công cụ | H39: Thời gian kết quả bịa. | I39: Sửa thời gian | J39: Cao | K39: NGAY_KQ đã bị gán trước nên đoạn lấy NGAY_TH_YL/NGAY_YL từ XML3 phía sau không bao giờ chạy. | L39: Khoa/người nhập sửa trên HIS rồi xuất lại; công cụ chỉ được CẢNH BÁO, không tự sửa. | M39: FIX_XML4.cs:34
A40: 39 | B40: XML4 | C40: XML4 – Chỉ số CLS | D40: MA_BS_DOC_KQ | E40: Rỗng | F40: Lấy MA_BAC_SI (người CHỈ ĐỊNH) của dòng XML3 cùng MA_DICH_VU; không thấy → CCHN trưởng khoa | G40: HIS: "" → Cổng: bác sĩ chỉ định / trưởng khoa | H40: Người đọc kết quả trên cổng không phải người đọc thật → sai trách nhiệm chuyên môn. | I40: Gán người khác | J40: Nghiêm trọng | K40: So khớp dòng [0] thay vì [j] → lấy nhầm bác sĩ của dòng khác trong cùng nhóm. | L40: Bắt buộc ký đọc kết quả trên LIS/PACS. | M40: FIX_XML4.cs:49
...

Sheet Ma ICD bi doi
A1: STT | B1: Mã trên HIS | C1: Mã gửi cổng | D1: Kiểu thay | E1: Áp dụng ở
A2: 1 | B2: U62.152 | C2: M15 | D2: Thay CHUỖI CON (Replace) – luôn chạy | E2: XML1, XML3, XML13, XML14
A3: 2 | B3: A91 | C3: A90 | D3: Thay CHUỖI CON (Replace) – luôn chạy | E3: XML1, XML3, XML13, XML14
A4: 3 | B4: I84 | C4: K64 | D4: Thay CHUỖI CON (Replace) – luôn chạy | E4: XML1, XML3, XML13, XML14
A5: 4 | B5: N18.0 | C5: N18 | D5: Thay CHUỖI CON (Replace) – luôn chạy | E5: XML1, XML3, XML13, XML14
A6: 5 | B6: U58.091 | C6: I10 | D6: Thay CHUỖI CON (Replace) – luôn chạy | E6: XML1, XML3, XML13, XML14
A7: 6 | B7: U55.561 | C7: G51 | D7: Thay CHUỖI CON (Replace) – luôn chạy | E7: XML1, XML3, XML13, XML14
A8: 7 | B8: A06.4 | C8: A06.4† | D8: So khớp nguyên mã – "TT mới áp dụng 1.7.2026" | E8: XML1, XML13, XML14 (không áp dụng XML3)
A9: 8 | B9: A06.8† | C9: A06.8 | D9: So khớp nguyên mã – "TT mới áp dụng 1.7.2026" | E9: XML1, XML13, XML14 (không áp dụng XML3)
A10: 9 | B10: C85.0 | C10: C85.9 | D10: So khớp nguyên mã – "TT mới áp dụng 1.7.2026" | E10: XML1, XML13, XML14 (không áp dụng XML3)
A11: 10 | B11: C94.1 | C11: D45 | D11: So khớp nguyên mã – "TT mới áp dụng 1.7.2026" | E11: XML1, XML13, XML14 (không áp dụng XML3)
A12: 11 | B12: D63 | C12: D63.8* | D12: So khớp nguyên mã – "TT mới áp dụng 1.7.2026" | E12: XML1, XML13, XML14 (không áp dụng XML3)
A13: 12 | B13: D75.2 | C13: D47.3 | D13: So khớp nguyên mã – "TT mới áp dụng 1.7.2026" | E13: XML1, XML13, XML14 (không áp dụng XML3)
... A34: 33 | B34: G02 | C34: G02.8* | D34: So khớp nguyên mã – "TT mới áp dụng 1.7.2026" | E34: XML1, XML13, XML14 (không áp dụng XML3)

Sheet Ma Z bi xoa
A1: STT | B1: Mã ICD bị loại khỏi MA_BENH_KT
A2: 1 | B2: Z00.0
A3: 2 | B3: Z00.1
A4: 3 | B4: Z00.2
A5: 4 | B5: Z00.3
A6: 5 | B6: Z00.4
A7: 6 | B7: Z00.5
A8: 7 | B8: Z00.6
A9: 8 | B9: Z00.8
A10: 9 | B10: Z01
A11: 10 | B11: Z01.0
A12: 11 | B12: Z01.1
A13: 12 | B13: Z01.2
... A105: 104 | B105: Z00

Sheet Ma VT gan cung
A1: STT | B1: MA_DICH_VU (XML3) | C1: MA_VAT_TU bị gán khi rỗng
A2: 1 | B2: 19.0187.1835 | C2: 40P.16+40P.52
A3: 2 | B3: 19.0114.1828 | C3: 40P.26
A4: 3 | B4: 19.0115.1856 | C4: 40P.26
A5: 4 | B5: 19.0118.1862 | C5: 40P.26
A6: 5 | B6: 19.0120.1862 | C6: 40P.26
A7: 6 | B7: 19.0340.1871 | C7: 40P.26
A8: 7 | B8: 19.0341.1870 | C8: 40P.26
A9: 8 | B9: 19.0342.1870 | C9: 40P.26
A10: 9 | B10: 12.0360.1870 | C10: 40P.26
A11: 10 | B11: 12.0362.1870 | C11: 40P.26
A12: 11 | B12: 19.0177.1838 | C12: 40P.35+40P.52
A13: 12 | B13: 19.0174.1866 | C13: 40P.36+40P.52
... A72: 71 | B72: 19.0366.1873 | C72: 40P.48

Sheet Truong khoa gan thay
A1: STT | B1: Mã khoa | C1: Mã CCHN bị gán | D1: Họ tên bị gán (XML7.TEN_BS)
A2: 1 | B2: K01 | C2: 002108/BYT-CCHN | D2: NGUYỄN THỊ BÍCH NGỌC
A3: 2 | B3: K01.1 | C3: 002108/BYT-CCHN | D3: NGUYỄN THỊ BÍCH NGỌC
A4: 3 | B4: K01.2 | C4: 0010532/BYT-CCHN | D4: ĐÀO HÙNG HẠNH
A5: 4 | B5: K02 | C5: 0010527/BYT-CCHN | D5: NGUYỄN ANH TUẤN
A6: 5 | B6: K02.1 | C6: 0010527/BYT-CCHN | D6: NGUYỄN ANH TUẤN
A7: 6 | B7: K02.2 | C7: 002176/BYT-CCHN | D7: MAI DUY TÔN
A8: 7 | B8: K04 | C8: 0013955/BYT-CCHN | D8: PHẠM MẠNH HÙNG
A9: 8 | B9: K04.1 | C9: 0013955/BYT-CCHN | D9: PHẠM MẠNH HÙNG
A10: 9 | B10: K05 | C10: 0012675/BYT-CCHN | D10: NGUYỄN CÔNG LONG
A11: 10 | B11: K06 | C11: 012890/BYT-CCHN | D11: NGUYỄN VĂN HÙNG
A12: 11 | B12: K07 | C12: 0009381/BYT-CCHN | D12: NGHIÊM TRUNG DŨNG
A13: 12 | B13: K08 | C13: 000606/BYT-CCHN | D13: NGUYỄN QUANG BẢY
... A53: 52 | B53: K52 | C53: 029029/BYT-CCHN | D53: PHẠM THỊ VIỆT DUNG
B55: Dùng khi MA_BAC_SI (XML2, XML3), MA_BS_DOC_KQ (XML4), NGUOI_THUC_HIEN (XML5), MA_BS (XML7, XML11) rỗng; và cho MA_TTDV (XML7, 8, 9, 13, 14) tại cơ sở chính.
