Workbook

Sheet Tổng quan hệ thống
A1: BÁO CÁO TỔNG QUAN HỆ THỐNG TIỀN GIÁM ĐỊNH XML3176
A2: Kỳ báo cáo: hồ sơ BHYT ra viện 01/10–15/10/2026 tại cơ sở 01929 và 37470 (dữ liệu nạp lại ngày 16/10/2026). Số liệu chốt ngày 16/10/2026 từ CSDL thật (truy vấn chỉ đọc); bộ kiểm commit 63e21fa8. Các ô tính từ sheet khác là công thức, tự cập nhật khi sheet nguồn thay đổi.
A4: 1. Hệ thống Tiền giám định làm gì
A5: • Mục đích: kiểm tra hồ sơ XML theo Quyết định 3176/QĐ-BYT TRƯỚC khi gửi cổng giám định BHXH, phát hiện sai sót để sửa tại nguồn (HIS, PACS/LIS, danh mục, khoa/phòng), giảm hồ sơ bị BHXH từ chối hoặc xuất toán.
A6: • Luồng xử lý: (1) Nạp XML từ HIS → (2) Kiểm tự động từng hồ sơ: 12 bảng XML và kiểm tổng thể toàn hồ sơ (XMLComplete) → (3) Có lỗi CHẶN GỬI: hồ sơ dừng, đơn vị sửa rồi nạp lại; chỉ có CẢNH BÁO: hồ sơ đi tiếp → (4) Xuất XML, ký số → (5) Gửi cổng giám định BHXH.
A7: • Nguyên tắc: không tự sửa dữ liệu trên bản gửi cổng (khác hệ thống FIXERROR – xem sheet "Đối chiếu FIXERROR"); mỗi mã lỗi gán một đơn vị chủ trì và đơn vị phối hợp để giao việc (sheet "Danh mục lỗi").
A9: 2. Quy mô dữ liệu và danh mục
A10: Chỉ tiêu | B10: Giá trị | C10: Ghi chú
A11: Hồ sơ trong kỳ | B11: 23967 | C11: Cơ sở 01929: 18.845; cơ sở 37470: 5.122
A12: Dòng chi tiết được kiểm | B12: 3816571 | C12: Thuốc XML2: 560.375; DVKT/VTYT XML3: 955.173; cận lâm sàng XML4: 2.091.705; diễn biến XML5: 209.318
A13: Chi phí BHYT thanh toán (T_BHTT, tỷ đồng) | B13: 216.33 | C13: Tổng T_BHTT trên XML1 của các hồ sơ trong kỳ
A14: Mã lỗi trong danh mục | B14: 252 | C14: Đang kiểm 215 mã, trong đó 137 mã chặn gửi; còn lại đã tắt hoặc đã gộp vào mã mới
A15: Mã lỗi phát sinh trong kỳ | B15: =COUNTIF('Danh mục lỗi'!$G$5:$G$222,">0") -> 116 | C15: Đếm từ sheet "Danh mục lỗi"
A16: Danh mục DVKT | B16: 24318 | C16: Cơ sở 01929: 8.595; cơ sở 37470: 15.723
A17: Danh mục thuốc | B17: 8689
A18: Danh mục VTYT | B18: 5243
A19: Danh mục nhân viên y tế (NVYT) | B19: 5089
A20: Danh mục trang thiết bị (mã máy) | B20: 8298
A21: DVKT bắt buộc có mã máy | B21: 3471 | C21: Căn cứ quy tắc thiếu mã máy từ 16/10/2026
A22: Cặp vật phẩm kèm DVKT | B22: 756 | C22: Thuốc/VTYT phải kèm đúng DVKT mẹ (quy tắc R1/R2)
A23: DVKT bắt buộc kèm vật phẩm | B23: 37 | C23: Quy tắc R3
A24: Danh mục cơ sở KCB | B24: 13843
A25: Danh mục ICD-10 | B25: 17075
A26: Tốc độ kiểm | B26: ≈ 0,36 giây/hồ sơ | C26: Đo trên 200 hồ sơ mẫu ngày 15/10/2026; mỗi hồ sơ một lượt kiểm; sửa danh mục có hiệu lực ngay, không cần khởi động lại
A28: 3. Kết quả kiểm trong kỳ
A29: Trạng thái hồ sơ | B29: Số hồ sơ | C29: % hồ sơ | D29: T_BHTT (tỷ đồng) | E29: % T_BHTT | F29: Ý nghĩa
A30: Tổng hồ sơ | B30: 23967 | C30: 1 | D30: 216.33 | E30: 1
A31: Không có lỗi | B31: 1995 | C31: =B31/$B$30 -> 0.083239454 | D31: 3.44 | E31: =D31/$D$30 -> 0.015901632 | F31: Đạt hoàn toàn
A32: Chỉ có cảnh báo | B32: 10432 | C32: =B32/$B$30 -> 0.43526516 | D32: 37.44 | E32: =D32/$D$30 -> 0.17306892 | F32: Được xuất, ký, gửi nhưng có nguy cơ BHXH giảm trừ
A33: Bị chặn gửi (≥ 1 lỗi chặn) | B33: 11540 | C33: =B33/$B$30 -> 0.48149539 | D33: 175.45 | E33: =D33/$D$30 -> 0.81102945 | F33: Không được xuất/ký/gửi đến khi sửa và nạp lại
A34: Đã xuất XML | B34: 12424 | C34: =B34/$B$30 -> 0.51837944 | D34: Khớp số hồ sơ không bị chặn
A35: Đã ký số | B35: 12429 | C35: =B35/$B$30 -> 0.51858806
A36: Đã gửi cổng qua Tiền giám định | B36: 0 | C36: =B36/$B$30 -> 0 | D36: Chưa gửi hồ sơ nào của kỳ này; lần gửi cổng gần nhất qua Tiền giám định là 29/09/2026
A38: 4. Theo cơ sở KCB
A39: Cơ sở | B39: Số hồ sơ | C39: Bị chặn | D39: % bị chặn | E39: Không lỗi | F39: T_BHTT (tỷ đồng) | G39: T_BHTT hồ sơ bị chặn (tỷ đồng)
A40: Cơ sở 01929 | B40: 18845 | C40: 9547 | D40: =C40/B40 -> 0.50660653 | E40: 1585 | F40: 174.4 | G40: 143.96
A41: Cơ sở 37470 | B41: 5122 | C41: 1993 | D41: =C41/B41 -> 0.38910582 | E41: 410 | F41: 41.93 | G41: 31.48
A42: Cộng | B42: =SUM(B40:B41) -> 23967 | C42: =SUM(C40:C41) -> 11540 | D42: =C42/B42 -> 0.48149539 | E42: =SUM(E40:E41) -> 1995 | F42: =SUM(F40:F41) -> 216.33 | G42: =SUM(G40:G41) -> 175.44
A44: 5. Theo loại khám chữa bệnh (MA_LOAI_KCB)
A45: Loại KCB | B45: Số hồ sơ | C45: Bị chặn | D45: % bị chặn | E45: Không lỗi | F45: T_BHTT (tỷ đồng) | G45: T_BHTT hồ sơ bị chặn (tỷ đồng)
...

Sheet Tổng hợp
A1: TỔNG HỢP LỖI TIỀN GIÁM ĐỊNH THEO ĐƠN VỊ VÀ NHÓM LỖI
A2: Tự tính từ sheet "Danh mục lỗi" (23.967 hồ sơ BHYT ra viện 01/10–15/10/2026 (nạp lại ngày 16/10/2026)). Chỉ đếm mã lỗi đã phát sinh (Số hồ sơ > 0). "Lượt hồ sơ-lỗi" = tổng số hồ sơ của các mã, một hồ sơ nhiều lỗi được đếm nhiều lần.
A4: 1. Theo đơn vị chủ trì
A5: Đơn vị chủ trì | B5: Số mã lỗi phát sinh | C5: Trong đó chặn gửi | D5: Lượt hồ sơ-lỗi | E5: Lượt hồ sơ-lỗi chặn gửi | F5: Mã lỗi lớn nhất
A6: Phòng BHYT | B6: =COUNTIFS('Danh mục lỗi'!$L$5:$L$222,$A6,'Danh mục lỗi'!$G$5:$G$222,">0") -> 32 | C6: =COUNTIFS('Danh mục lỗi'!$L$5:$L$222,$A6,'Danh mục lỗi'!$G$5:$G$222,">0",'Danh mục lỗi'!$E$5:$E$222,"Có") -> 21 | D6: =SUMIFS('Danh mục lỗi'!$G$5:$G$222,'Danh mục lỗi'!$L$5:$L$222,$A6) -> 12127 | E6: =SUMIFS('Danh mục lỗi'!$G$5:$G$222,'Danh mục lỗi'!$L$5:$L$222,$A6,'Danh mục lỗi'!$E$5:$E$222,"Có") -> 1177 | F6: XML3_OVERLAPPING_BED_USAGE (8.117 HS)
A7: CNTT | B7: =COUNTIFS('Danh mục lỗi'!$L$5:$L$222,$A7,'Danh mục lỗi'!$G$5:$G$222,">0") -> 23 | C7: =COUNTIFS('Danh mục lỗi'!$L$5:$L$222,$A7,'Danh mục lỗi'!$G$5:$G$222,">0",'Danh mục lỗi'!$E$5:$E$222,"Có") -> 9 | D7: =SUMIFS('Danh mục lỗi'!$G$5:$G$222,'Danh mục lỗi'!$L$5:$L$222,$A7) -> 62282 | E7: =SUMIFS('Danh mục lỗi'!$G$5:$G$222,'Danh mục lỗi'!$L$5:$L$222,$A7,'Danh mục lỗi'!$E$5:$E$222,"Có") -> 10107 | F7: XML4_CHI_SO_EMPTY (17.415 HS)
A8: Khoa Dược | B8: =COUNTIFS('Danh mục lỗi'!$L$5:$L$222,$A8,'Danh mục lỗi'!$G$5:$G$222,">0") -> 8 | C8: =COUNTIFS('Danh mục lỗi'!$L$5:$L$222,$A8,'Danh mục lỗi'!$G$5:$G$222,">0",'Danh mục lỗi'!$E$5:$E$222,"Có") -> 1 | D8: =SUMIFS('Danh mục lỗi'!$G$5:$G$222,'Danh mục lỗi'!$L$5:$L$222,$A8) -> 17221 | E8: =SUMIFS('Danh mục lỗi'!$G$5:$G$222,'Danh mục lỗi'!$L$5:$L$222,$A8,'Danh mục lỗi'!$E$5:$E$222,"Có") -> 396 | F8: XML2_INVALID_DANG_BAO_CHE (7.033 HS)
A9: Phòng VT-TBYT | B9: =COUNTIFS('Danh mục lỗi'!$L$5:$L$222,$A9,'Danh mục lỗi'!$G$5:$G$222,">0") -> 6 | C9: =COUNTIFS('Danh mục lỗi'!$L$5:$L$222,$A9,'Danh mục lỗi'!$G$5:$G$222,">0",'Danh mục lỗi'!$E$5:$E$222,"Có") -> 2 | D9: =SUMIFS('Danh mục lỗi'!$G$5:$G$222,'Danh mục lỗi'!$L$5:$L$222,$A9) -> 19568 | E9: =SUMIFS('Danh mục lỗi'!$G$5:$G$222,'Danh mục lỗi'!$L$5:$L$222,$A9,'Danh mục lỗi'!$E$5:$E$222,"Có") -> 32 | F9: XML3_INFO_ERROR_MA_MAY_NOT_FOUND (18.854 HS)
A10: Phòng KHTH | B10: =COUNTIFS('Danh mục lỗi'!$L$5:$L$222,$A10,'Danh mục lỗi'!$G$5:$G$222,">0") -> 4 | C10: =COUNTIFS('Danh mục lỗi'!$L$5:$L$222,$A10,'Danh mục lỗi'!$G$5:$G$222,">0",'Danh mục lỗi'!$E$5:$E$222,"Có") -> 4 | D10: =SUMIFS('Danh mục lỗi'!$G$5:$G$222,'Danh mục lỗi'!$L$5:$L$222,$A10) -> 15601 | E10: =SUMIFS('Danh mục lỗi'!$G$5:$G$222,'Danh mục lỗi'!$L$5:$L$222,$A10,'Danh mục lỗi'!$E$5:$E$222,"Có") -> 15601 | F10: XML3_INVALID_MA_DICH_VU (7.344 HS)
A11: Phòng TCKT | B11: =COUNTIFS('Danh mục lỗi'!$L$5:$L$222,$A11,'Danh mục lỗi'!$G$5:$G$222,">0") -> 1 | C11: =COUNTIFS('Danh mục lỗi'!$L$5:$L$222,$A11,'Danh mục lỗi'!$G$5:$G$222,">0",'Danh mục lỗi'!$E$5:$E$222,"Có") -> 0 | D11: =SUMIFS('Danh mục lỗi'!$G$5:$G$222,'Danh mục lỗi'!$L$5:$L$222,$A11) -> 232 | E11: =SUMIFS('Danh mục lỗi'!$G$5:$G$222,'Danh mục lỗi'!$L$5:$L$222,$A11,'Danh mục lỗi'!$E$5:$E$222,"Có") -> 0 | F11: XML3_INVALID_APPROVED_DON_GIA_BH (232 HS)
A12: Phòng TCCB | B12: =COUNTIFS('Danh mục lỗi'!$L$5:$L$222,$A12,'Danh mục lỗi'!$G$5:$G$222,">0") -> 1 | C12: =COUNTIFS('Danh mục lỗi'!$L$5:$L$222,$A12,'Danh mục lỗi'!$G$5:$G$222,">0",'Danh mục lỗi'!$E$5:$E$222,"Có") -> 0 | D12: =SUMIFS('Danh mục lỗi'!$G$5:$G$222,'Danh mục lỗi'!$L$5:$L$222,$A12) -> 10455 | E12: =SUMIFS('Danh mục lỗi'!$G$5:$G$222,'Danh mục lỗi'!$L$5:$L$222,$A12,'Danh mục lỗi'!$E$5:$E$222,"Có") -> 0 | F12: XMLComplete_NVYT_KHONG_CO_TRONG_DM (10.455 HS)
A13: Khoa lâm sàng | B13: =COUNTIFS('Danh mục lỗi'!$L$5:$L$222,$A13,'Danh mục lỗi'!$G$5:$G$222,">0") -> 33 | C13: =COUNTIFS('Danh mục lỗi'!$L$5:$L$222,$A13,'Danh mục lỗi'!$G$5:$G$222,">0",'Danh mục lỗi'!$E$5:$E$222,"Có") -> 25 | D13: =SUMIFS('Danh mục lỗi'!$G$5:$G$222,'Danh mục lỗi'!$L$5:$L$222,$A13) -> 19204 | E13: =SUMIFS('Danh mục lỗi'!$G$5:$G$222,'Danh mục lỗi'!$L$5:$L$222,$A13,'Danh mục lỗi'!$E$5:$E$222,"Có") -> 2232 | F13: XML8_TOMTAT_KQ_TOO_SHORT (7.258 HS)
A14: Tiếp đón | B14: =COUNTIFS('Danh mục lỗi'!$L$5:$L$222,$A14,'Danh mục lỗi'!$G$5:$G$222,">0") -> 8 | C14: =COUNTIFS('Danh mục lỗi'!$L$5:$L$222,$A14,'Danh mục lỗi'!$G$5:$G$222,">0",'Danh mục lỗi'!$E$5:$E$222,"Có") -> 4 | D14: =SUMIFS('Danh mục lỗi'!$G$5:$G$222,'Danh mục lỗi'!$L$5:$L$222,$A14) -> 451 | E14: =SUMIFS('Danh mục lỗi'!$G$5:$G$222,'Danh mục lỗi'!$L$5:$L$222,$A14,'Danh mục lỗi'!$E$5:$E$222,"Có") -> 19 | F14: XML1_ADMIN_INFO_ERROR_SO_CCCD (420 HS)
A15: Đơn vị PM Tiền giám định | B15: =COUNTIFS('Danh mục lỗi'!$L$5:$L$222,$A15,'Danh mục lỗi'!$G$5:$G$222,">0") -> 0 | C15: =COUNTIFS('Danh mục lỗi'!$L$5:$L$222,$A15,'Danh mục lỗi'!$G$5:$G$222,">0",'Danh mục lỗi'!$E$5:$E$222,"Có") -> 0 | D15: =SUMIFS('Danh mục lỗi'!$G$5:$G$222,'Danh mục lỗi'!$L$5:$L$222,$A15) -> 0 | E15: =SUMIFS('Danh mục lỗi'!$G$5:$G$222,'Danh mục lỗi'!$L$5:$L$222,$A15,'Danh mục lỗi'!$E$5:$E$222,"Có") -> 0 | F15: (không còn lỗi)
A16: Tổng | B16: =SUM(B6:B15) -> 116 | C16: =SUM(C6:C15) -> 66 | D16: =SUM(D6:D15) -> 157141 | E16: =SUM(E6:E15) -> 29564
A18: 2. Theo nhóm lỗi (nghiệp vụ / kỹ thuật)
A19: Phân nhóm | B19: Số mã lỗi phát sinh | C19: Trong đó chặn gửi | D19: Lượt hồ sơ-lỗi | E19: Lượt hồ sơ-lỗi chặn gửi | F19: Ý nghĩa
A20: Nghiệp vụ – Chuyên môn lâm sàng | B20: =COUNTIFS('Danh mục lỗi'!$K$5:$K$222,$A20,'Danh mục lỗi'!$G$5:$G$222,">0") -> 33 | C20: =COUNTIFS('Danh mục lỗi'!$K$5:$K$222,$A20,'Danh mục lỗi'!$G$5:$G$222,">0",'Danh mục lỗi'!$E$5:$E$222,"Có") -> 25 | D20: =SUMIFS('Danh mục lỗi'!$G$5:$G$222,'Danh mục lỗi'!$K$5:$K$222,$A20) -> 19204 | E20: =SUMIFS('Danh mục lỗi'!$G$5:$G$222,'Danh mục lỗi'!$K$5:$K$222,$A20,'Danh mục lỗi'!$E$5:$E$222,"Có") -> 2232 | F20: Bác sĩ/điều dưỡng nhập thiếu, sai nội dung chuyên môn
A21: Nghiệp vụ – Quy định BHYT | B21: =COUNTIFS('Danh mục lỗi'!$K$5:$K$222,$A21,'Danh mục lỗi'!$G$5:$G$222,">0") -> 32 | C21: =COUNTIFS('Danh mục lỗi'!$K$5:$K$222,$A21,'Danh mục lỗi'!$G$5:$G$222,">0",'Danh mục lỗi'!$E$5:$E$222,"Có") -> 21 | D21: =SUMIFS('Danh mục lỗi'!$G$5:$G$222,'Danh mục lỗi'!$K$5:$K$222,$A21) -> 12127 | E21: =SUMIFS('Danh mục lỗi'!$G$5:$G$222,'Danh mục lỗi'!$K$5:$K$222,$A21,'Danh mục lỗi'!$E$5:$E$222,"Có") -> 1177 | F21: Khai sai quy định thanh toán BHYT (đối tượng, mức hưởng, ngày giường, công khám)
A22: Nghiệp vụ – Hành chính, tiếp đón | B22: =COUNTIFS('Danh mục lỗi'!$K$5:$K$222,$A22,'Danh mục lỗi'!$G$5:$G$222,">0") -> 8 | C22: =COUNTIFS('Danh mục lỗi'!$K$5:$K$222,$A22,'Danh mục lỗi'!$G$5:$G$222,">0",'Danh mục lỗi'!$E$5:$E$222,"Có") -> 4 | D22: =SUMIFS('Danh mục lỗi'!$G$5:$G$222,'Danh mục lỗi'!$K$5:$K$222,$A22) -> 451 | E22: =SUMIFS('Danh mục lỗi'!$G$5:$G$222,'Danh mục lỗi'!$K$5:$K$222,$A22,'Danh mục lỗi'!$E$5:$E$222,"Có") -> 19 | F22: Tiếp đón nhập thiếu thông tin hành chính
A23: Nghiệp vụ – Danh mục | B23: =COUNTIFS('Danh mục lỗi'!$K$5:$K$222,$A23,'Danh mục lỗi'!$G$5:$G$222,">0") -> 20 | C23: =COUNTIFS('Danh mục lỗi'!$K$5:$K$222,$A23,'Danh mục lỗi'!$G$5:$G$222,">0",'Danh mục lỗi'!$E$5:$E$222,"Có") -> 7 | D23: =SUMIFS('Danh mục lỗi'!$G$5:$G$222,'Danh mục lỗi'!$K$5:$K$222,$A23) -> 63077 | E23: =SUMIFS('Danh mục lỗi'!$G$5:$G$222,'Danh mục lỗi'!$K$5:$K$222,$A23,'Danh mục lỗi'!$E$5:$E$222,"Có") -> 16029 | F23: Danh mục thuốc, VTYT, DVKT, NVYT, TTB, giá chưa khớp danh mục BHXH phê duyệt
A24: Kỹ thuật – HIS | B24: =COUNTIFS('Danh mục lỗi'!$K$5:$K$222,$A24,'Danh mục lỗi'!$G$5:$G$222,">0") -> 11 | C24: =COUNTIFS('Danh mục lỗi'!$K$5:$K$222,$A24,'Danh mục lỗi'!$G$5:$G$222,">0",'Danh mục lỗi'!$E$5:$E$222,"Có") -> 4 | D24: =SUMIFS('Danh mục lỗi'!$G$5:$G$222,'Danh mục lỗi'!$K$5:$K$222,$A24) -> 16230 | E24: =SUMIFS('Danh mục lỗi'!$G$5:$G$222,'Danh mục lỗi'!$K$5:$K$222,$A24,'Danh mục lỗi'!$E$5:$E$222,"Có") -> 27 | F24: HIS không bắt buộc nhập, tính sai, xuất sai định dạng
A25: Kỹ thuật – Tích hợp HIS–PACS | B25: =COUNTIFS('Danh mục lỗi'!$K$5:$K$222,$A25,'Danh mục lỗi'!$G$5:$G$222,">0") -> 2 | C25: =COUNTIFS('Danh mục lỗi'!$K$5:$K$222,$A25,'Danh mục lỗi'!$G$5:$G$222,">0",'Danh mục lỗi'!$E$5:$E$222,"Có") -> 1 | D25: =SUMIFS('Danh mục lỗi'!$G$5:$G$222,'Danh mục lỗi'!$K$5:$K$222,$A25) -> 2242 | E25: =SUMIFS('Danh mục lỗi'!$G$5:$G$222,'Danh mục lỗi'!$K$5:$K$222,$A25,'Danh mục lỗi'!$E$5:$E$222,"Có") -> 432 | F25: PACS/RIS trả kết quả thiếu thông tin về HIS
A26: Kỹ thuật – Tích hợp HIS–LIS | B26: =COUNTIFS('Danh mục lỗi'!$K$5:$K$222,$A26,'Danh mục lỗi'!$G$5:$G$222,">0") -> 3 | C26: =COUNTIFS('Danh mục lỗi'!$K$5:$K$222,$A26,'Danh mục lỗi'!$G$5:$G$222,">0",'Danh mục lỗi'!$E$5:$E$222,"Có") -> 2 | D26: =SUMIFS('Danh mục lỗi'!$G$5:$G$222,'Danh mục lỗi'!$K$5:$K$222,$A26) -> 22259 | E26: =SUMIFS('Danh mục lỗi'!$G$5:$G$222,'Danh mục lỗi'!$K$5:$K$222,$A26,'Danh mục lỗi'!$E$5:$E$222,"Có") -> 4844 | F26: LIS trả kết quả thiếu mã/tên chỉ số, giá trị
A27: Kỹ thuật – Tích hợp HIS–PACS/LIS | B27: =COUNTIFS('Danh mục lỗi'!$K$5:$K$222,$A27,'Danh mục lỗi'!$G$5:$G$222,">0") -> 7 | C27: =COUNTIFS('Danh mục lỗi'!$K$5:$K$222,$A27,'Danh mục lỗi'!$G$5:$G$222,">0",'Danh mục lỗi'!$E$5:$E$222,"Có") -> 2 | D27: =SUMIFS('Danh mục lỗi'!$G$5:$G$222,'Danh mục lỗi'!$K$5:$K$222,$A27) -> 21551 | E27: =SUMIFS('Danh mục lỗi'!$G$5:$G$222,'Danh mục lỗi'!$K$5:$K$222,$A27,'Danh mục lỗi'!$E$5:$E$222,"Có") -> 4804 | F27: PACS và LIS cùng mắc: tài khoản máy thay mã CCHN, thiếu người thực hiện, mã máy, thời gian KQ
A28: Kỹ thuật – Phần mềm Tiền giám định | B28: =COUNTIFS('Danh mục lỗi'!$K$5:$K$222,$A28,'Danh mục lỗi'!$G$5:$G$222,">0") -> 0 | C28: =COUNTIFS('Danh mục lỗi'!$K$5:$K$222,$A28,'Danh mục lỗi'!$G$5:$G$222,">0",'Danh mục lỗi'!$E$5:$E$222,"Có") -> 0 | D28: =SUMIFS('Danh mục lỗi'!$G$5:$G$222,'Danh mục lỗi'!$K$5:$K$222,$A28) -> 0 | E28: =SUMIFS('Danh mục lỗi'!$G$5:$G$222,'Danh mục lỗi'!$K$5:$K$222,$A28,'Danh mục lỗi'!$E$5:$E$222,"Có") -> 0 | F28: Thiếu sót của chính phần mềm kiểm (danh mục CSKCB, mã thừa)
A29: Cộng Nghiệp vụ | B29: =COUNTIFS('Danh mục lỗi'!$J$5:$J$222,"Nghiệp vụ",'Danh mục lỗi'!$G$5:$G$222,">0") -> 93 | C29: =COUNTIFS('Danh mục lỗi'!$J$5:$J$222,"Nghiệp vụ",'Danh mục lỗi'!$G$5:$G$222,">0",'Danh mục lỗi'!$E$5:$E$222,"Có") -> 57 | D29: =SUMIFS('Danh mục lỗi'!$G$5:$G$222,'Danh mục lỗi'!$J$5:$J$222,"Nghiệp vụ") -> 94859 | E29: =SUMIFS('Danh mục lỗi'!$G$5:$G$222,'Danh mục lỗi'!$J$5:$J$222,"Nghiệp vụ",'Danh mục lỗi'!$E$5:$E$222,"Có") -> 19457
A30: Cộng Kỹ thuật | B30: =COUNTIFS('Danh mục lỗi'!$J$5:$J$222,"Kỹ thuật",'Danh mục lỗi'!$G$5:$G$222,">0") -> 23 | C30: =COUNTIFS('Danh mục lỗi'!$J$5:$J$222,"Kỹ thuật",'Danh mục lỗi'!$G$5:$G$222,">0",'Danh mục lỗi'!$E$5:$E$222,"Có") -> 9 | D30: =SUMIFS('Danh mục lỗi'!$G$5:$G$222,'Danh mục lỗi'!$J$5:$J$222,"Kỹ thuật") -> 62282 | E30: =SUMIFS('Danh mục lỗi'!$G$5:$G$222,'Danh mục lỗi'!$J$5:$J$222,"Kỹ thuật",'Danh mục lỗi'!$E$5:$E$222,"Có") -> 10107

Sheet Trọng tâm theo đơn vị
A1: TRỌNG TÂM CẦN XỬ LÝ THEO TỪNG ĐƠN VỊ (để báo cáo)
A2: Số liệu là số hồ sơ có lỗi trong 23.967 hồ sơ BHYT ra viện 01/10–15/10/2026 (nạp lại ngày 16/10/2026) (bộ kiểm commit 63e21fa8). Chi tiết từng mã ở sheet "Danh mục lỗi".
A4: STT | B4: Đơn vị | C4: Nhóm | D4: Vấn đề | E4: Mã lỗi / số hồ sơ | F4: Việc cần làm
A5: 1 | B5: CNTT + hãng PACS/LIS | C5: Kỹ thuật – Tích hợp HIS–PACS/LIS | D5: PACS/LIS trả TÀI KHOẢN MÁY thay mã CCHN người đọc kết quả: vietrad 2.460 HS, mitalab 866, sys 66; thêm tên đăng nhập cá nhân (pqa1, LQH, ntdh3…). Tổng ~3.274 HS | E5: XMLComplete_NVYT_SAI_DINH_DANG (BS đọc KQ XML4): 3.274 HS | F5: Kết nối PACS/LIS ánh xạ tài khoản → mã CCHN; cấm ký kết quả bằng tài khoản dùng chung
A6: 2 | B6: CNTT + hãng LIS (Mitalab) | C6: Kỹ thuật – Tích hợp HIS–LIS | D6: LIS trả chỉ số thiếu mã và tên chỉ số, 91% ở Tổng phân tích tế bào máu 22.0121.1369 (còn lại: đường máu mao mạch 01.0281.1510, khí máu 23.0103.1531) | E6: XML4_CHI_SO_EMPTY: 17.415 HS | F6: Bổ sung ánh xạ chỉ số trên LIS cho các xét nghiệm bị lỗi
A7: 3 | B7: CNTT | C7: Kỹ thuật – HIS | D7: HIS gửi số CCCD/mã BHXH (12 số) vào NGUOI_THUC_HIEN thay vì mã CCHN: 54 người, ~1.367 HS (4 người có trong DM NVYT theo số định danh) | E7: XMLComplete_NVYT_SAI_DINH_DANG (phần số định danh) | F7: Xuất mã CCHN/GPHN, không xuất số định danh
A8: 4 | B8: CNTT | C8: Kỹ thuật – HIS / thiết bị | D8: Giờ thực hiện DVKT ghi theo lúc bấm: < 3 phút, giờ thực hiện = giờ kết quả (Điện tim, Đường máu mao mạch tại giường) | E8: UNDER_3MIN 4.865; NGAY_TH_YL = NGAY_KQ 6.758; dài bất thường (mới, cảnh báo) 438 HS | F8: Lấy giờ bắt đầu/kết thúc thật từ thiết bị/phiếu thực hiện
A9: 5 | B9: CNTT | C9: Kỹ thuật – HIS | D9: Thiếu người thực hiện, mã máy, thủ trưởng đơn vị khi xuất XML (HIS không bắt buộc / chưa cấu hình người ký). Từ 15/10 quy tắc thiếu mã máy căn cứ danh mục DVKT cần mã máy (thay lọc theo nhóm 1/2/3) nên số hồ sơ thiếu mã máy tăng | E9: Người TH trống 3.105; mã máy trống 9.985; thủ trưởng đơn vị 373 HS | F9: Bắt buộc nhập trên HIS; cấu hình người ký thủ trưởng cho từng loại giấy
A10: 6 | B10: Phòng KHTH | C10: Nghiệp vụ – Danh mục | D10: Danh mục DVKT cơ sở 01929 thiếu (8.595 dòng so với 15.723 của 37470), nhiều mã CĐHA (X-quang ngực 18.0119.0028); tên DVKT khác tên phê duyệt | E10: INVALID_MA_DICH_VU 7.344; XML4 mã DV 7.332; sai tên 858 HS | F10: Nhập đủ danh mục DVKT đã phê duyệt cho 01929
A11: 7 | B11: Phòng TCCB + Phòng BHYT | C11: Nghiệp vụ – Danh mục | D11: NVYT (CCHN) chưa có/chưa được duyệt trên cổng BHXH; trạng thái duyệt trên cổng đổi từ 08/10 | E11: XMLComplete_NVYT_KHONG_CO_TRONG_DM 10.455 HS: người TH XML3 9.714; BS đọc KQ XML4 9.292; BS chỉ định XML3 1.535; XML5 1.159; XML2 1.134; XML14 407 | F11: Rà soát, đăng ký bổ sung NVYT lên cổng; cập nhật DM NVYT vào phần mềm
A12: 8 | B12: Phòng TCKT | C12: Nghiệp vụ – Danh mục | D12: Giá DVKT trên HIS cao hơn giá phê duyệt (chưa chặn gửi nhưng BHXH sẽ xuất toán phần chênh) | E12: XML3_INVALID_APPROVED_DON_GIA_BH: 232 HS | F12: Đối chiếu bảng giá
A13: 9 | B13: Phòng VT-TBYT | C13: Nghiệp vụ – Danh mục | D13: Danh mục trang thiết bị (mã máy) chưa đủ; VTYT ngoài danh mục / sai tên / vượt giá | E13: Mã máy không có 18.854; VTYT ngoài DM 72; sai tên 475 HS | F13: Cập nhật danh mục TTB, VTYT theo thầu
A14: 10 | B14: Khoa Dược | C14: Nghiệp vụ – Danh mục | D14: Thuốc lệch danh mục được duyệt: dạng bào chế, ĐVT, đường dùng, tên, mã, thầu, SĐK, hàm lượng, giá | E14: Dạng bào chế 7.033; ĐVT: đã tắt kiểm 15/10; đường dùng 2.231; mã 396; tên 2.089 HS | F14: Đối chiếu, sửa danh mục thuốc HIS (luật hàm lượng/thầu đã sửa 12/10 – số liệu trước đó có báo nhầm)
A15: 11 | B15: Phòng BHYT | C15: Nghiệp vụ – Quy định BHYT | D15: Ngày giường (trùng giường, thiếu so với TT39, chưa khai ngày cộng thêm), thừa công khám nội trú, mức hưởng vượt quyền lợi thẻ, PT lần 2 thanh toán 100% | E15: Trùng giường 8.117; ngày cộng TT39 1.264; thừa công khám 480; mức hưởng 514 HS | F15: Rà quy tắc ngày giường/công khám/mức hưởng trên HIS cùng CNTT; giám sát tiếp đón
A16: 12 | B16: Khoa lâm sàng (qua Phòng KHTH) | C16: Nghiệp vụ – Chuyên môn lâm sàng | D16: Bác sĩ chỉ định = người thực hiện; tóm tắt kết quả ghi "xem hs BA"; diễn biến sao chép; liều dùng sai định dạng; thiếu PP điều trị | E16: Cùng BS 4.779; tóm tắt ngắn 7.258; diễn biến trùng 1.583 HS | F16: Phổ biến quy định, kiểm tra hồ sơ trước khi khoá bệnh án
... A18: 14 | B18: Đơn vị PM Tiền giám định | C18: Kỹ thuật – Phần mềm | D18: Cơ sở 37470 từng chưa có trong danh mục CSKCB của phần mềm kiểm → chặn oan. ĐÃ XỬ LÝ: kiểm lại 16/10/2026 không còn hồ sơ lỗi | E18: XML1_ADMIN_INFO_ERROR_MA_CSKCB_NOT_FOUND: 0 HS | F18: Đã bổ sung 37470 vào DM CSKCB — không cần xử lý thêm

Sheet Tài khoản thay CCHN
A1: MÃ NGƯỜI ĐỌC KẾT QUẢ / NGƯỜI THỰC HIỆN KHÔNG PHẢI MÃ CCHN
A2: Tách từ XMLComplete_NVYT_SAI_DINH_DANG (từ 15/10/2026 thay XML4_INFO_ERROR_MA_BS_DOC_KQ_NOT_FOUND và XML3_INFO_ERROR_NGUOI_THUC_HIEN_NOT_FOUND), 23.967 hồ sơ BHYT ra viện 01/10–15/10/2026 (nạp lại ngày 16/10/2026).
A4: Giá trị gửi lên | B4: Trường | C4: Số hồ sơ | D4: Loại | E4: Nguồn | F4: Dịch vụ điển hình | G4: Xử lý
A5: vietrad | B5: MA_BS_DOC_KQ (XML4) | C5: 2460 | D5: Tài khoản hệ thống PACS | E5: Tích hợp HIS–PACS | F5: Siêu âm ổ bụng 18.0015.0001; X-quang ngực thẳng 18.0119.0028 | G5: PACS trả mã CCHN của bác sĩ ký kết quả
A6: mitalab | B6: MA_BS_DOC_KQ (XML4) | C6: 866 | D6: Tài khoản hệ thống LIS | E6: Tích hợp HIS–LIS | F6: Tổng phân tích tế bào máu 22.0121.1369; Khí máu 23.0103.1531; Tủy đồ 22.0129.1415 | G6: LIS trả mã CCHN của người duyệt kết quả
A7: sys | B7: MA_BS_DOC_KQ (XML4) | C7: 66 | D7: Tài khoản quản trị | E7: Tích hợp HIS–PACS | F7: Siêu âm ổ bụng, Siêu âm tuyến giáp | G7: Không cho ký kết quả bằng tài khoản quản trị
A8: pqa1, LQH, ntdh3, phn3, dtt15, vttq2, TTH39, dsl, vannh, hvh3, bvt, pat, pthai, dht1, ptc4, ndb11, ntt73, nxg… | B8: MA_BS_DOC_KQ (XML4) | C8: 208 | D8: Tên đăng nhập cá nhân | E8: Tích hợp HIS–PACS/LIS | F8: X-quang (PACS) … | G8: Ánh xạ tên đăng nhập → mã CCHN
A9: 028322, 32161, 25092, 028605… | B9: MA_BS_DOC_KQ (XML4) | C9: 21 | D9: Số thiếu phần /BYT-CCHN | E9: Tích hợp HIS–PACS/LIS | G9: Trả đủ mã CCHN
A10: Số CCCD/mã BHXH 12 chữ số (54 người) | B10: NGUOI_THUC_HIEN (XML3) | C10: 1367 | D10: Số định danh thay mã CCHN | E10: HIS | G10: HIS xuất mã CCHN/GPHN; 4 người khớp DM NVYT theo số định danh
A11: CNTT | B11: NGUOI_THUC_HIEN (XML3) | C11: 1 | D11: Tài khoản dùng chung | E11: HIS | G11: Không cho tài khoản CNTT thực hiện DVKT
A13: Ghi chú: mã CCHN đúng định dạng nhưng chưa có/chưa được duyệt trong danh mục NVYT (XMLComplete_NVYT_KHONG_CO_TRONG_DM) – BS đọc KQ XML4: 43 mã, 9.292 HS; người thực hiện XML3: 65 mã, 9.714 HS → thuộc Phòng TCCB/Phòng BHYT.

Sheet Danh mục lỗi
A1: PHÂN LOẠI DANH MỤC LỖI XML3176 THEO NGUỒN PHÁT SINH VÀ ĐƠN VỊ XỬ LÝ
A2: Số hồ sơ: 23.967 hồ sơ BHYT ra viện 01/10–15/10/2026 (nạp lại ngày 16/10/2026), kiểm lại bằng bộ kiểm hiện tại (commit 63e21fa8, chế độ chỉ đọc) ngày 16/10/2026, không lỗi chạy. Cột P = số hồ sơ của CÙNG nhóm hồ sơ khi kiểm sáng 16/10, trước khi nạp lại (23.254 hồ sơ có trong lần kiểm đó) – để thấy lỗi nào đã giảm sau khi sửa. Đã bỏ 37 mã cũ không còn dùng (đã gộp vào mã mới hoặc đang tắt kiểm). Một hồ sơ có thể mang nhiều mã lỗi nên không cộng dồn số hồ sơ giữa các dòng.
A4: STT | B4: Mã lỗi | C4: XML | D4: Tên lỗi | E4: Chặn gửi | F4: Đang kiểm | G4: Số hồ sơ | H4: % hồ sơ | I4: Ví dụ thực tế | J4: Nhóm lớn | K4: Phân nhóm | L4: Đơn vị chủ trì | M4: Đơn vị phối hợp | N4: Hướng xử lý | O4: FIXERROR hệ thống khác tự sửa (quy tắc số) | P4: Số HS trước khi nạp lại (kiểm sáng 16/10)
A5: 1 | B5: XML3_INFO_ERROR_MA_MAY_NOT_FOUND | C5: XML3 | D5: Mã máy không tồn tại trong danh mục trang thiết bị | E5: Không | F5: Có | G5: 18854 | H5: =G5/23967 -> 0.786665 | I5: Mã máy không tồn tại: ĐX.2.000895 | J5: Nghiệp vụ | K5: Nghiệp vụ – Danh mục | L5: Phòng VT-TBYT | M5: Phòng BHYT; CNTT | N5: Cập nhật danh mục trang thiết bị (mã máy) lên cổng và vào phần mềm | P5: 18264
A6: 2 | B6: XML4_CHI_SO_EMPTY | C6: XML4 | D6: Mã/tên chỉ số để trống | E6: Không | F6: Có | G6: 17415 | H6: =G6/23967 -> 0.72662411 | I6: Dòng có giá trị/đơn vị đo nhưng thiếu mã chỉ số và tên chỉ số. Dịch vụ: 22.0121.1369 | J6: Kỹ thuật | K6: Kỹ thuật – Tích hợp HIS–LIS | L6: CNTT | M6: Hãng LIS (Mitalab); Khoa Xét nghiệm | N6: Bổ sung ánh xạ mã/tên chỉ số trên kết nối LIS → HIS (gộp hai mã cũ mã chỉ số trống + tên chỉ số trống từ 15/10) | P6: 16844
A7: 3 | B7: XMLComplete_NVYT_KHONG_CO_TRONG_DM | C7: XMLComplete | D7: Mã nhân viên y tế không có trong danh mục NVYT | E7: Không | F7: Có | G7: 10455 | H7: =G7/23967 -> 0.43622481 | I7: 032154/BYT-CCHN không có trong danh mục NVYT — người thực hiện XML3 (1 dòng: Siêu âm doppler tim, van tim), BS đọc KQ XML4 (1 dòng: 18.0052.0004) | J7: Nghiệp vụ | K7: Nghiệp vụ – Danh mục | L7: Phòng TCCB | M7: Phòng BHYT; CNTT | N7: Rà soát, đăng ký bổ sung NVYT lên cổng; cập nhật DM NVYT vào phần mềm (gộp các mã NVYT "không tồn tại" cũ từ 15/10) | O7: #35 | P7: 10181
A8: 4 | B8: XML3_INFO_ERROR_GROUP_CODE_MA_MAY | C8: XML3 | D8: Thiếu mã máy | E8: Không | F8: Có | G8: 9985 | H8: =G8/23967 -> 0.41661451 | I8: Mã máy không được để trống đối với DVKT: Đốt sóng cao tần điều trị ung thư gan (RFA) dưới hướng dẫn siêu âm (mã 18.0614.0063) | J8: Kỹ thuật | K8: Kỹ thuật – Tích hợp HIS–PACS/LIS | L8: CNTT | M8: Phòng VT-TBYT; Hãng PACS; Hãng LIS | N8: Kết nối thiết bị/PACS/LIS trả mã máy thực hiện; HIS bắt buộc mã máy với DVKT yêu cầu | P8: 9717
A9: 5 | B9: XML3_OVERLAPPING_BED_USAGE | C9: XML3 | D9: Giường sử dụng trùng lặp | E9: Không | F9: Có | G9: 8117 | H9: =G9/23967 -> 0.33867401 | I9: Giường T008 tại khoa K14 sử dụng trùng lặp trong khoảng thời gian từ 09/10/2026 20:49 đến 10/10/2026 20:49. Trùng lặp với hồ sơ có mã: 000007379048 (NGAY_TH_YL: 10/10/2026 11:00, NGAY_KQ: 10/10/2026 1 | J9: Nghiệp vụ | K9: Nghiệp vụ – Quy định BHYT | L9: Phòng BHYT | M9: Khoa lâm sàng; CNTT | N9: Rà soát chỉ định ngày giường, công khám, khoa chỉ định đúng quy định BHYT | P9: 7727
A10: 6 | B10: XML3_INVALID_MA_DICH_VU | C10: XML3 | D10: Mã dịch vụ không tồn tại | E10: Có | F10: Có | G10: 7344 | H10: =G10/23967 -> 0.30642133 | I10: Dịch vụ không tồn tại trong DM DVKT: _TB | J10: Nghiệp vụ | K10: Nghiệp vụ – Danh mục | L10: Phòng KHTH | M10: Phòng BHYT; CNTT | N10: Nhập đủ danh mục DVKT đã được BHXH phê duyệt (cơ sở 01929 chỉ có 8.123 dòng so với 15.660 của 37470); tên DVKT trên HIS theo đúng tên phê duyệt | P10: 7177
A11: 7 | B11: XML4_INFO_ERROR_MA_DICH_VU_NOT_FOUND | C11: XML4 | D11: Mã dịch vụ không tồn tại | E11: Có | F11: Có | G11: 7332 | H11: =G11/23967 -> 0.30592064 | I11: Mã dịch vụ không tồn tại trong danh mục DVKT: 24.0108.1720.SC2 | J11: Nghiệp vụ | K11: Nghiệp vụ – Danh mục | L11: Phòng KHTH | M11: Phòng BHYT; CNTT | N11: Nhập đủ danh mục DVKT đã được BHXH phê duyệt (cơ sở 01929 chỉ có 8.123 dòng so với 15.660 của 37470); tên DVKT trên HIS theo đúng tên phê duyệt | P11: 7167
A12: 8 | B12: XML8_TOMTAT_KQ_TOO_SHORT | C12: XML8 | D12: Tóm tắt kết quả quá ngắn | E12: Không | F12: Có | G12: 7258 | H12: =G12/23967 -> 0.30283306 | I12: Tóm tắt kết quả chỉ 9 ký tự (< 20): "xem hs BA" | J12: Nghiệp vụ | K12: Nghiệp vụ – Chuyên môn lâm sàng | L12: Khoa lâm sàng | M12: Phòng KHTH | N12: Bác sĩ nhập đủ, đúng nội dung chuyên môn trên HIS; Phòng KHTH kiểm tra | O12: #47 | P12: 6815
A13: 9 | B13: XML2_INVALID_DANG_BAO_CHE | C13: XML2 | D13: Dạng bào chế không khớp danh mục | E13: Không | F13: Có | G13: 7033 | H13: =G13/23967 -> 0.29344515 | I13: Mã thuốc: 40.980; Dạng bào chế không khớp danh mục: "Hỗn dịch xịt qua bình định kiều điều áp" # danh mục: "Hỗn dịch xịt qua bình định liều điều áp" | J13: Nghiệp vụ | K13: Nghiệp vụ – Danh mục | L13: Khoa Dược | M13: Phòng BHYT; CNTT | N13: Khoa Dược đối chiếu danh mục thuốc trên HIS với danh mục được duyệt (mã, tên, hàm lượng, SĐK, thầu, đường dùng, dạng bào chế, ĐVT, giá) | P13: 6778
A14: 10 | B14: XML3_NGAY_TH_YL_EQUALS_NGAY_KQ | C14: XML3 | D14: Thời gian thực hiện y lệnh trùng thời gian kết quả | E14: Không | F14: Có | G14: 6758 | H14: =G14/23967 -> 0.28197104 | I14: NGAY_TH_YL = NGAY_KQ = 31/08/2026 23:11. Dịch vụ: Xét nghiệm đường máu mao mạch tại giường (một lần) | J14: Kỹ thuật | K14: Kỹ thuật – HIS | L14: CNTT | M14: Khoa lâm sàng; Khoa thăm dò chức năng | N14: Giờ bắt đầu/kết thúc phải là giờ thực hiện thật, không lấy giờ bấm trả kết quả (Điện tim, Đường máu mao mạch tại giường…) | O14: #33 | P14: 6475
A15: 11 | B15: XML3_EXECUTION_TIME_UNDER_3MIN | C15: XML3 | D15: Thời gian thực hiện nhỏ hơn quy định | E15: Không | F15: Có | G15: 4865 | H15: =G15/23967 -> 0.20298744 | I15: Nhóm 3: thực hiện 2 phút (< 3). Dịch vụ: Đo đa ký hô hấp | J15: Kỹ thuật | K15: Kỹ thuật – HIS | L15: CNTT | M15: Khoa lâm sàng; Khoa thăm dò chức năng | N15: Giờ bắt đầu/kết thúc phải là giờ thực hiện thật, không lấy giờ bấm trả kết quả (Điện tim, Đường máu mao mạch tại giường…) | O15: #33 | P15: 4685
A16: 12 | B16: XML3_SAME_DOCTOR_ORDER_AND_EXECUTE | C16: XML3 | D16: Bác sĩ vừa ra y lệnh vừa thực hiện | E16: Không | F16: Có | G16: 4779 | H16: =G16/23967 -> 0.19939917 | I16: Mã bác sĩ = người thực hiện = 5301/BP-CCHN. Dịch vụ: Định nhóm máu tại giường bệnh trước truyền máu [khối hồng cầu, khối bạch cầu] | J16: Nghiệp vụ | K16: Nghiệp vụ – Chuyên môn lâm sàng | L16: Khoa lâm sàng | M16: Phòng KHTH; CNTT | N16: Rà soát quy trình chỉ định – thực hiện; không gán giờ/người đồng loạt | O16: #35 | P16: 4694
A17: 13 | B17: XMLComplete_NVYT_SAI_DINH_DANG | C17: XMLComplete | D17: Mã nhân viên y tế sai định danh | E17: Không | F17: Có | G17: 4141 | H17: =G17/23967 -> 0.17277924 | I17: vietrad là tài khoản/tên đăng nhập, không phải mã CCHN — BS đọc KQ XML4 (1 dòng: 18.0015.0001) | J17: Kỹ thuật | K17: Kỹ thuật – Tích hợp HIS–PACS/LIS | L17: CNTT | M17: Hãng PACS (Vietrad); Hãng LIS (Mitalab); Phòng TCCB | N17: PACS/LIS/HIS trả mã CCHN thay cho tài khoản/số định danh – xem sheet "Tài khoản thay CCHN" | O17: #39 | P17: 4401
A18: 14 | B18: XML2_LIEU_DUNG_UNIT_INVALID | C18: XML2 | D18: Đơn vị trong liều dùng khác đơn vị tính của thuốc | E18: Không | F18: Có | G18: 4025 | H18: =G18/23967 -> 0.16793925 | I18: Đơn vị trong liều dùng (Ống) khác đơn vị tính của thuốc (Đơn vị) | J18: Kỹ thuật | K18: Kỹ thuật – HIS | L18: CNTT | M18: Phòng KHTH; Khoa Dược | N18: Sửa ánh xạ/định dạng dữ liệu khi HIS xuất XML; bắt buộc nhập trường còn thiếu | P18: 3847
A19: 15 | B19: XML4_XN_MISSING_VALUE_RESULT | C19: XML4 | D19: Xét nghiệm không nhập giá trị và kết quả | E19: Có | F19: Có | G19: 3753 | H19: =G19/23967 -> 0.15659031 | I19: Chỉ số Đo độ ngưng tập tiểu cầu với Ristocetin trong huyết tương giàu tiểu cầu không có giá trị/mô tả/kết luận. Dịch vụ: 22.0042.1288 | J19: Kỹ thuật | K19: Kỹ thuật – Tích hợp HIS–LIS | L19: CNTT | M19: Hãng LIS (Mitalab); Khoa Xét nghiệm | N19: LIS trả đủ giá trị/kết luận theo chỉ số; kết quả dạng chữ (vi sinh) đưa vào KET_LUAN/MO_TA | P19: 3845
A20: 16 | B20: XMLComplete_NVYT_THIEU | C20: XMLComplete | D20: Thiếu mã nhân viên y tế | E20: Có | F20: Có | G20: 3533 | H20: =G20/23967 -> 0.14741102 | I20: Thiếu mã người thực hiện ở 1 dòng: XML3 (1 dòng: Siêu âm ổ bụng (gan mật, tụy, lách, thận, bàng quang)). | J20: Kỹ thuật | K20: Kỹ thuật – Tích hợp HIS–PACS/LIS | L20: CNTT | M20: Khoa Xét nghiệm; Khoa CĐHA; Khoa lâm sàng | N20: Bắt buộc nhập người thực hiện/BS đọc KQ trên HIS; cấu hình người ký thủ trưởng (gộp các mã NVYT "để trống" cũ từ 15/10) | O20: #35 | P20: 4050
A21: 17 | B21: XML2_INVALID_DRUG_CONCENTRATION | C21: XML2 | D21: Mã thuốc sai hàm lượng trong danh mục BHYT | E21: Không | F21: Có | G21: 2810 | H21: =G21/23967 -> 0.11724454 | I21: Mã thuốc: 40.980; Sai hàm lượng: 5mg/2,5ml | J21: Nghiệp vụ | K21: Nghiệp vụ – Danh mục | L21: Khoa Dược | M21: Phòng BHYT; CNTT | N21: Khoa Dược đối chiếu danh mục thuốc trên HIS với danh mục được duyệt (mã, tên, hàm lượng, SĐK, thầu, đường dùng, dạng bào chế, ĐVT, giá) | P21: 2718
A22: 18 | B22: XML2_INVALID_DUONG_DUNG | C22: XML2 | D22: Đường dùng không khớp danh mục | E22: Không | F22: Có | G22: 2231 | H22: =G22/23967 -> 0.093086327 | I22: Mã thuốc: 40.883; Đường dùng không khớp danh mục: "6.01" # danh mục: "Dùng ngoài / 3.05" | J22: Nghiệp vụ | K22: Nghiệp vụ – Danh mục | L22: Khoa Dược | M22: Phòng BHYT; CNTT | N22: Khoa Dược đối chiếu danh mục thuốc trên HIS với danh mục được duyệt (mã, tên, hàm lượng, SĐK, thầu, đường dùng, dạng bào chế, ĐVT, giá) | P22: 2154
A23: 19 | B23: XML2_INVALID_DRUG_NAME | C23: XML2 | D23: Mã thuốc sai tên trong danh mục BHYT | E23: Không | F23: Có | G23: 2089 | H23: =G23/23967 -> 0.087161514 | I23: Mã thuốc: 40.974; Thuốc sai tên so với danh mục được duyệt: Symbicort Turbuhaler # Symbicort Turbuhaler 60 Dose 160/4.5 | J23: Nghiệp vụ | K23: Nghiệp vụ – Danh mục | L23: Khoa Dược | M23: Phòng BHYT; CNTT | N23: Khoa Dược đối chiếu danh mục thuốc trên HIS với danh mục được duyệt (mã, tên, hàm lượng, SĐK, thầu, đường dùng, dạng bào chế, ĐVT, giá) | P23: 2043
A24: 20 | B24: XML3_INVALID_NGAY_KQ | C24: XML3 | D24: Ngày trả kết quả không hợp lệ | E24: Không | F24: Có | G24: 2031 | H24: =G24/23967 -> 0.08474152 | I24: Ngày trả kết quả (NGAY_KQ) không nằm trong khoảng thời gian vào (31/08/2026 08:54) và ra (08/09/2026 15:50) | J24: Kỹ thuật | K24: Kỹ thuật – Tích hợp HIS–PACS/LIS | L24: CNTT | M24: Khoa CĐHA; Khoa Xét nghiệm | N24: Thống nhất một nguồn thời gian trả kết quả giữa PACS/LIS và HIS; rà ca trả kết quả sau ra viện | O24: #32 | P24: 1110
A25: 21 | B25: XML4_INFO_ERROR_MO_TA_EMPTY | C25: XML4 | D25: Mô tả không được để trống | E25: Không | F25: Có | G25: 1810 | H25: =G25/23967 -> 0.075520507 | I25: Mô tả không được để trống đối với DVKT: 19.0222.0050.K.01916 | J25: Kỹ thuật | K25: Kỹ thuật – Tích hợp HIS–PACS | L25: CNTT | M25: Hãng PACS; Khoa CĐHA; Khoa Y học hạt nhân | N25: PACS/RIS trả đủ mô tả và kết luận; khoa CĐHA không duyệt kết quả trống | P25: 1691
A26: 22 | B26: XML5_DIEN_BIEN_DUPLICATE | C26: XML5 | D26: Diễn biến điều trị trùng nhau | E26: Không | F26: Có | G26: 1583 | H26: =G26/23967 -> 0.066049151 | I26: Diễn biến lâm sàng trùng với dòng STT 9: "Diễn biến: Y lệnh thuốc; Theo dõi - chăm sóc: Chăm sóc cấp 2 Chế độ ăn BT05 Theo dõi toàn trạng, mạ" | J26: Nghiệp vụ | K26: Nghiệp vụ – Chuyên môn lâm sàng | L26: Khoa lâm sàng | M26: Phòng KHTH | N26: Bác sĩ nhập đủ, đúng nội dung chuyên môn trên HIS; Phòng KHTH kiểm tra | P26: 1522
A27: 23 | B27: XML2_PRICE_EXCEEDS_APPROVED | C27: XML2 | D27: Giá thuốc cao hơn giá được duyệt | E27: Không | F27: Có | G27: 1578 | H27: =G27/23967 -> 0.065840531 | I27: Mã thuốc: 40.974; Giá cao hơn giá được duyệt: 434000 > 219000.00 | J27: Nghiệp vụ | K27: Nghiệp vụ – Danh mục | L27: Khoa Dược | M27: Phòng BHYT; CNTT | N27: Khoa Dược đối chiếu danh mục thuốc trên HIS với danh mục được duyệt (mã, tên, hàm lượng, SĐK, thầu, đường dùng, dạng bào chế, ĐVT, giá) | P27: 1524
A28: 24 | B28: XML3_SERVICE_GROUP_PTTT_DUPLICATE | C28: XML3 | D28: PTTT trùng y lệnh | E28: Không | F28: Có | G28: 1432 | H28: =G28/23967 -> 0.059748821 | I28: - Mã điều trị=000007450973; stt=9; Bác sĩ=047397/BYT-CCHN; Ngày yl=13/10/2026 16:56; Ngày th=13/10/2026 16:56; Ngày kq=13/10/2026 17:00 | J28: Nghiệp vụ | K28: Nghiệp vụ – Chuyên môn lâm sàng | L28: Khoa lâm sàng | M28: Phòng KHTH; CNTT | N28: Rà soát quy trình chỉ định – thực hiện; không gán giờ/người đồng loạt | P28: 1372
A29: 25 | B29: XML3_OVERLAPPING_SERVICE_EXECUTION | C29: XML3 | D29: Thời gian thực hiện trùng với dịch vụ khác | E29: Không | F29: Có | G29: 1296 | H29: =G29/23967 -> 0.054074352 | I29: Dịch vụ 28.0110.0584 (20/09/2026 00:11 - 20/09/2026 00:31) chồng thời gian thực hiện với dịch vụ 15.0301.0218 (20/09/2026 00:11 - 20/09/2026 00:31) trong cùng hồ sơ. | J29: Nghiệp vụ | K29: Nghiệp vụ – Chuyên môn lâm sàng | L29: Khoa lâm sàng | M29: Phòng KHTH; CNTT | N29: Rà soát quy trình chỉ định – thực hiện; không gán giờ/người đồng loạt | P29: 1260
A30: 26 | B30: XML4_INFO_ERROR_NGAY_KQ | C30: XML4 | D30: Thiếu ngày trả kết quả | E30: Có | F30: Có | G30: 1271 | H30: =G30/23967 -> 0.053031251 | I30: Ngày trả kết quả không được để trống | J30: Kỹ thuật | K30: Kỹ thuật – Tích hợp HIS–PACS/LIS | L30: CNTT | M30: Hãng PACS; Hãng LIS; Khoa CĐHA; Khoa Xét nghiệm | N30: Bắt buộc ký số/duyệt kết quả trên PACS/LIS trước khi đẩy về HIS | O30: #38 | P30: 1912
A31: 27 | B31: XMLComplete_BED_DAYS_SPECIAL_NOT_CLAIMED | C31: XMLComplete | D31: Trường hợp đặc biệt được cộng 1 ngày giường nhưng chưa khai | E31: Không | F31: Có | G31: 1264 | H31: =G31/23967 -> 0.052739183 | I31: Được cộng 1 ngày giường theo TT39 (loại ra viện 4 - Xin ra viện): được 9, đã khai 8 — chưa khai ngày được cộng thêm. | J31: Nghiệp vụ | K31: Nghiệp vụ – Quy định BHYT | L31: Phòng BHYT | M31: CNTT; Phòng TCKT | N31: Sửa cách HIS tính ngày giường theo TT39 / thanh toán PT lần 2 trong ngày | P31: 1214
A32: 28 | B32: XML4_INFO_ERROR_GIA_TRI_LENGTH | C32: XML4 | D32: Giá trị quá dài | E32: Có | F32: Có | G32: 1091 | H32: =G32/23967 -> 0.045520925 | I32: Giá trị không được lớn hơn 50 kí tự: Vi khuẩn:Cầu trực khuẩn Gram (-) 1(+) Bạch cầu đa nhân: ( ++) | J32: Kỹ thuật | K32: Kỹ thuật – Tích hợp HIS–LIS | L32: CNTT | M32: Hãng LIS (Mitalab); Khoa Xét nghiệm | N32: LIS trả đủ giá trị/kết luận theo chỉ số; kết quả dạng chữ (vi sinh) đưa vào KET_LUAN/MO_TA | O32: #37 | P32: 1007
A33: 29 | B33: XML2_INVALID_REGISTRATION_NUMBER | C33: XML2 | D33: Mã thuốc sai số đăng ký trong danh mục BHYT | E33: Không | F33: Có | G33: 997 | H33: =G33/23967 -> 0.041598865 | I33: Mã thuốc: 40.692; Số ĐK: 300110997524 | J33: Nghiệp vụ | K33: Nghiệp vụ – Danh mục | L33: Khoa Dược | M33: Phòng BHYT; CNTT | N33: Khoa Dược đối chiếu danh mục thuốc trên HIS với danh mục được duyệt (mã, tên, hàm lượng, SĐK, thầu, đường dùng, dạng bào chế, ĐVT, giá) | P33: 988
A34: 30 | B34: XML3_INVALID_TEN_DICH_VU | C34: XML3 | D34: Tên dịch vụ kỹ thuật khác tên được phê duyệt | E34: Có | F34: Có | G34: 858 | H34: =G34/23967 -> 0.035799224 | I34: Mã DVKT: 22.0307.1306 có tên: Nghiệm pháp Coombs gián tiếp (Kỹ thuật Scangel/Gelcard trên máy tự động); Tên phê duyệt: Nghiệm pháp Coombs gián tiếp (kỹ thuật Scangel/Gelcard trên máy tự động) | J34: Nghiệp vụ | K34: Nghiệp vụ – Danh mục | L34: Phòng KHTH | M34: Phòng BHYT; CNTT | N34: Nhập đủ danh mục DVKT đã được BHXH phê duyệt (cơ sở 01929 chỉ có 8.123 dòng so với 15.660 của 37470); tên DVKT trên HIS theo đúng tên phê duyệt | P34: 828
A35: 31 | B35: XML3_BED_DAY_QUANTITY_ERROR | C35: XML3 | D35: Chỉ định ngày giường > 1 | E35: Không | F35: Có | G35: 857 | H35: =G35/23967 -> 0.0357575 | I35: Số lượng ngày giường > 1. Ngày y lệnh: 31/08/2026 07:58 | J35: Nghiệp vụ | K35: Nghiệp vụ – Quy định BHYT | L35: Phòng BHYT | M35: Khoa lâm sàng; CNTT | N35: Rà soát chỉ định ngày giường, công khám, khoa chỉ định đúng quy định BHYT | P35: 837
A36: 32 | B36: XML7_INFO_ERROR_PP_DIEUTRI | C36: XML7 | D36: Thiếu phương pháp điều trị | E36: Có | F36: Có | G36: 642 | H36: =G36/23967 -> 0.026786832 | I36: Phương pháp điều trị không được để trống | J36: Nghiệp vụ | K36: Nghiệp vụ – Chuyên môn lâm sàng | L36: Khoa lâm sàng | M36: Phòng KHTH | N36: Bác sĩ nhập đủ, đúng nội dung chuyên môn trên HIS; Phòng KHTH kiểm tra | O36: #44 | P36: 548
A37: 33 | B37: XML8_INFO_ERROR_PP_DIEUTRI | C37: XML8 | D37: Thiếu phương pháp điều trị | E37: Có | F37: Có | G37: 636 | H37: =G37/23967 -> 0.026536488 | I37: Phương pháp điều trị không được để trống | J37: Nghiệp vụ | K37: Nghiệp vụ – Chuyên môn lâm sàng | L37: Khoa lâm sàng | M37: Phòng KHTH | N37: Bác sĩ nhập đủ, đúng nội dung chuyên môn trên HIS; Phòng KHTH kiểm tra | O37: #47 | P37: 542
A38: 34 | B38: XMLComplete_XML4_NGAY_KQ_MISMATCH_XML3 | C38: XMLComplete | D38: Ngày KQ XML4 khác ngày KQ XML3 | E38: Không | F38: Có | G38: 582 | H38: =G38/23967 -> 0.02428339 | I38: Dịch vụ 19.0174.1866: ngày KQ XML4 (30/09/2026 15:06) khác ngày KQ XML3 | J38: Kỹ thuật | K38: Kỹ thuật – Tích hợp HIS–PACS/LIS | L38: CNTT | M38: Khoa CĐHA; Khoa Xét nghiệm | N38: Thống nhất một nguồn thời gian trả kết quả giữa PACS/LIS và HIS; rà ca trả kết quả sau ra viện | O38: #38 | P38: 491
A39: 35 | B39: XMLComplete_MUC_HUONG_EXCEEDS_ENTITLEMENT | C39: XMLComplete | D39: Mức hưởng khai vượt trần cho phép | E39: Có | F39: Có | G39: 514 | H39: =G39/23967 -> 0.021446155 | I39: Hồ sơ đúng tuyến: mức hưởng khai tối đa 100%, trần cho phép 95% (quyền lợi thẻ 95%). | J39: Nghiệp vụ | K39: Nghiệp vụ – Quy định BHYT | L39: Phòng BHYT | M39: Tiếp đón; CNTT | N39: Tiếp đón khai đúng mã đối tượng, giấy chuyển tuyến/hẹn, mức hưởng theo thẻ; HIS chặn khi thiếu | P39: 486
A40: 36 | B40: XMLComplete_ERROR_MULTIPLE_EXAMINATION_FEES_INPATIENT | C40: XMLComplete | D40: Thừa công khám cho Điều trị nội trú | E40: Có | F40: Có | G40: 480 | H40: =G40/23967 -> 0.020027538 | I40: Chỉ cho phép có một lần công khám, số lượng hiện tại: 5 | J40: Nghiệp vụ | K40: Nghiệp vụ – Quy định BHYT | L40: Phòng BHYT | M40: Khoa lâm sàng; CNTT | N40: Rà soát chỉ định ngày giường, công khám, khoa chỉ định đúng quy định BHYT | P40: 464
A41: 37 | B41: XML3_INVALID_MATERIAL_NAME | C41: XML3 | D41: Tên vật tư không khớp với danh mục phê duyệt | E41: Không | F41: Có | G41: 475 | H41: =G41/23967 -> 0.019818918 | I41: Mã VTYT: N08.00.310.3272.279.0002 có tên: Mặt nạ Oxy không túi các loại, các cỡ; Tên phê duyệt: Mask thở Oxy | J41: Nghiệp vụ | K41: Nghiệp vụ – Danh mục | L41: Phòng VT-TBYT | M41: Phòng BHYT; CNTT | N41: Đối chiếu danh mục VTYT trên HIS với danh mục được duyệt theo thầu | P41: 444
...

Sheet Đối chiếu FIXERROR
A1: ĐỐI CHIẾU: LỖI HỆ THỐNG KHÁC TỰ SỬA (FIXERROR) ↔ LỖI TIỀN GIÁM ĐỊNH CHẶN
A2: Nguồn quy tắc: fixerror-he-thong-khac-lech-his-cong.xlsx. Tiền giám định không tự sửa – chặn/cảnh báo để sửa tại nguồn.
A4: # | B4: Bảng | C4: Trường bị sửa | D4: FIXERROR tự sửa thế nào | E4: Mức độ (FIXERROR) | F4: Mã lỗi Tiền giám định tương ứng | G4: Số HS Tiền giám định bắt (mã lớn nhất) | H4: Nhóm lỗi | I4: Đơn vị sửa tại nguồn | J4: Còn dùng | K4: Ghi chú | N4: 18
A5: 1 | B5: XML1 | C5: MA_KHUVUC | D5: Xoá thành rỗng | E5: Trung bình | F5: XML1_ADMIN_INFO_ERROR_MA_KHUVUC XML1_DOI_TUONG_KCB_THIEU_MA_KHUVUC | G5: 0 | H5: Nghiệp vụ – Quy định BHYT | I5: Phòng BHYT | K5: Không dùng | M5: =59-21 -> 38
A6: 2 | B6: XML1 | C6: MATINH_CU_TRU | D6: Gán cứng "01" (Hà Nội) | E6: Cao | F6: XML1_ADMIN_INFO_ERROR_MATINH_CU_TRU | G6: 0 | H6: Nghiệp vụ – Hành chính, tiếp đón | I6: Tiếp đón | K6: Không dùng
A7: 3 | B7: XML1 | C7: MATINH_CU_TRU | D7: Lấy ký tự thứ 2–3 (Substring(1,2)) | E7: Trung bình | F7: XML1_ADMIN_INFO_ERROR_MATINH_CU_TRU_NOT_FOUND | G7: 6 | H7: Kỹ thuật – HIS | I7: CNTT | K7: Không dùng
A8: 4 | B8: XML1 | C8: DIA_CHI | D8: Ghép ".,<xã>,<huyện>,<tỉnh>" từ danh mục ĐVHC; không khớp thì ra ".,,," | E8: Cao | F8: Chưa có quy tắc tương ứng | K8: Không dùng
A9: 5 | B9: XML1 | C9: LY_DO_VV | D9: Gán chữ "LY_DO_VV" | E9: Cao | F9: XML1_ADMIN_INFO_ERROR_LY_DO_VV | G9: 1 | H9: Nghiệp vụ – Chuyên môn lâm sàng | I9: Khoa lâm sàng | K9: Không rõ
A10: 6 | B10: XML1 | C10: LY_DO_VNT | D10: Ghi đè LY_DO_VNT bằng 5 ký tự đầu của MA_BENH_CHINH | E10: Cao | F10: XML1_SPECIAL_INPATIENT_ERROR_MA_LY_DO_VNT | G10: 425 | H10: Nghiệp vụ – Chuyên môn lâm sàng | I10: Khoa lâm sàng | K10: Không rõ
A11: 7 | B11: XML1 | C11: LY_DO_VNT | D11: Gán chữ "LY_DO_VNT" | E11: Cao | F11: XML1_SPECIAL_INPATIENT_ERROR_LY_DO_VNT | G11: 0 | H11: Nghiệp vụ – Chuyên môn lâm sàng | I11: Khoa lâm sàng | K11: Không rõ
A12: 8 | B12: XML1 | C12: MA_NGHE_NGHIEP | D12: Gán "00" | E12: Trung bình | F12: XML1_ADMIN_INFO_ERROR_MA_NGHE_NGHIEP | G12: 0 | H12: Nghiệp vụ – Hành chính, tiếp đón | I12: Tiếp đón | K12: Không dùng
A13: 9 | B13: XML1 | C13: CAN_NANG | D13: Bịa cân nặng theo tuổi: ≤1 tuổi = 5 kg; 2 tuổi = 13; 3 = 14 … 17 tuổi = 40; ≥18 tuổi = 45 kg | E13: Nghiêm trọng | F13: XML1_ADMIN_INFO_ERROR_CAN_NANG | G13: 0 | H13: Nghiệp vụ – Hành chính, tiếp đón | I13: Tiếp đón | K13: Không rõ
A14: 10 | B14: XML1 | C14: CAN_NANG | D14: Chia 1000 (giả định nhập gam) | E14: Trung bình | F14: XML1_ADMIN_INFO_ERROR_TO_MUCH_CAN_NANG | G14: 6 | H14: Nghiệp vụ – Hành chính, tiếp đón | I14: Tiếp đón | K14: Không rõ
A15: 11 | B15: XML1 | C15: CAN_NANG_CON | D15: Làm tròn thành số nguyên | E15: Trung bình | F15: XMLComplete_CAN_NANG_CON_THIEU_XML9 | G15: 1 | H15: Kỹ thuật – HIS | I15: CNTT | K15: Không rõ
A16: 12 | B16: XML1 | C16: MA_BENH_CHINH, MA_BENH_KT | D16: Thay chuỗi con 6 mã: U62.152→M15; A91→A90; I84→K64; N18.0→N18; U58.091→I10; U55.561→G51 | E16: Nghiêm trọng | F16: XML1_DISEASE_ICD_CODE_ERROR_MA_BENH_CHINH XML1_DISEASE_ICD_CODE_ERROR_MA_BENH_KT | G16: 6 | H16: Nghiệp vụ – Chuyên môn lâm sàng | I16: Khoa lâm sàng | K16: Không rõ
A17: 13 | B17: XML1 | C17: MA_BENH_CHINH, MA_BENH_KT | D17: Đổi sang mã mới (xem sheet "Ma ICD bi doi") | E17: Nghiêm trọng | F17: XML1_DISEASE_ICD_CODE_ERROR_MA_BENH_CHINH XML1_DISEASE_ICD_CODE_ERROR_MA_BENH_KT | G17: 6 | H17: Nghiệp vụ – Chuyên môn lâm sàng | I17: Khoa lâm sàng | K17: Không dùng
A18: 14 | B18: XML1 | C18: MA_BENH_KT | D18: Loại bỏ khỏi chuỗi bệnh kèm theo (104 mã, xem sheet "Ma Z bi xoa") | E18: Cao | F18: XML1_WARNING_MA_BENH_KT XML1_WARNING_MA_BENH_CHINH | G18: 66 | H18: Nghiệp vụ – Chuyên môn lâm sàng | I18: Khoa lâm sàng | J18: x
A19: 15 | B19: XML1 | C19: MA_DOITUONG_KCB | D19: Suy đoán: tỷ lệ T_TONGCHI_BH/T_TONGCHI_BV ≤ 40% → "3"; khoa K02.1/K02.2 → "2"; còn lại → "1" | E19: Nghiêm trọng | F19: XML1_ADMIN_INFO_ERROR_MA_DOITUONG_KCB XML1_DOI_TUONG_KCB_NGOAI_DANH_MUC | G19: 0 | H19: Nghiệp vụ – Quy định BHYT | I19: Phòng BHYT | K19: Không dùng
A20: 16 | B20: XML1 | C20: PP_DIEU_TRI | D20: Rỗng → "PP_DIEU_TRI" + hằng BSKhongDienTT; dài → cắt 1296 ký tự + "..." | E20: Cao | F20: XML1_SPECIAL_INPATIENT_ERROR_PP_DIEU_TRI | G20: 7 | H20: Nghiệp vụ – Chuyên môn lâm sàng | I20: Khoa lâm sàng | J20: x
A21: 17 | B21: XML1 | C21: GIAY_CHUYEN_TUYEN | D21: Gán số giấy giả "...../20../PCCSKBCB" | E21: Nghiêm trọng | F21: XML1_ADMIN_INFO_ERROR_GIAY_CHUYEN_TUYEN XML1_DOI_TUONG_KCB_THIEU_GIAY_CHUYEN_TUYEN | G21: 8 | H21: Nghiệp vụ – Quy định BHYT | I21: Phòng BHYT | K21: Không dùng
A22: 18 | B22: XML2 | C22: MA_THUOC, TEN_THUOC | D22: Gán hằng BHYTConfig.DuocChuaNhapTT | E22: Cao | F22: XML2_INVALID_DRUG_CODE XML2_MISSING_DRUG_NAME | G22: 396 | H22: Nghiệp vụ – Danh mục | I22: Khoa Dược | K22: Không rõ
A23: 19 | B23: XML2 | C23: MA_THUOC | D23: Đổi thành "9.4.KTNAT" | E23: Cao | F23: XML2_INVALID_DRUG_CODE | G23: 396 | H23: Nghiệp vụ – Danh mục | I23: Khoa Dược | K23: Không rõ
A24: 20 | B24: XML2 | C24: SO_DANG_KY | D24: Gán DuocChuaNhapTT | E24: Trung bình | F24: Chưa có quy tắc tương ứng | K24: Không rõ
A25: 21 | B25: XML2 | C25: NGAY_YL | D25: Kéo NGAY_YL về đúng NGAY_RA / NGAY_VAO | E25: Nghiêm trọng | F25: XML2_INVALID_ORDER_TIME | G25: 1 | H25: Nghiệp vụ – Chuyên môn lâm sàng | I25: Khoa lâm sàng | J25: x
A26: 22 | B26: XML2 | C26: NGAY_TH_YL | D26: Gán NGAY_TH_YL = NGAY_YL | E26: Cao | F26: Chưa có quy tắc tương ứng | J26: x
A27: 23 | B27: XML2 | C27: MA_BAC_SI | D27: Bỏ "CNTT"; rỗng → gán mã CCHN TRƯỞNG KHOA theo MA_KHOA (xem sheet "Truong khoa gan thay") | E27: Nghiêm trọng | F27: XMLComplete_NVYT_THIEU (BS chỉ định XML2) XMLComplete_NVYT_KHONG_CO_TRONG_DM / _SAI_DINH_DANG (BS chỉ định XML2) | G27: 1134 | H27: Nghiệp vụ – Danh mục | I27: Phòng TCCB | J27: x
A28: 24 | B28: XML3 | C28: MA_BENH | D28: Thay chuỗi con 6 mã ICD như XML1 | E28: Nghiêm trọng | F28: XML3_INFO_ERROR_MA_BENH_INVALID | G28: 1 | H28: Nghiệp vụ – Chuyên môn lâm sàng | I28: Khoa lâm sàng | K28: Không dùng
A29: 25 | B29: XML3 | C29: MA_GIUONG | D29: Đổi thành H017 | E29: Cao | F29: XML3_INVALID_BED_CODE_FORMAT | G29: 0 | H29: Nghiệp vụ – Quy định BHYT | I29: Phòng BHYT | K29: Không dùng
A30: 26 | B30: XML3 | C30: MA_VAT_TU, TEN_VAT_TU (nhóm 10) | D30: Gán hằng BHYTConfig.PVTChuaNhapTT | E30: Cao | F30: XML3_MISSING_MATERIAL_CODE XML3_MISSING_MATERIAL_NAME | G30: 0 | H30: Kỹ thuật – HIS | I30: CNTT | K30: Không dùng
A31: 27 | B31: XML3 | C31: GOI_VTYT, MA_DICH_VU, TEN_DICH_VU (nhóm 10) | D31: Xoá cả 3 trường | E31: Nghiêm trọng | F31: Chưa có quy tắc tương ứng | K31: Không rõ
A32: 28 | B32: XML3 | C32: TAI_SU_DUNG (nhóm 10) | D32: Xoá cờ tái sử dụng | E32: Nghiêm trọng | F32: XML3_TAI_SU_DUNG_DON_GIA_LECH | G32: 0 | H32: Kỹ thuật – HIS | I32: CNTT | K32: Không rõ
A33: 29 | B33: XML3 | C33: MA_VAT_TU (DVKT y học hạt nhân) | D33: Gán CỨNG mã "40P.xx" (+ "40P.52") theo từng DVKT – xem sheet "Ma VT gan cung" | E33: Nghiêm trọng | F33: Chưa có quy tắc tương ứng | J33: x
A34: 30 | B34: XML3 | C34: NGAY_YL | D34: Kéo về NGAY_RA / NGAY_VAO | E34: Nghiêm trọng | F34: XML3_INVALID_ORDER_TIME | G34: 2 | H34: Nghiệp vụ – Chuyên môn lâm sàng | I34: Khoa lâm sàng | J34: x
A35: 31 | B35: XML3 | C35: MA_BAC_SI | D35: Bỏ "CNTT"; rỗng → CCHN trưởng khoa | E35: Nghiêm trọng | F35: XMLComplete_NVYT_THIEU (BS chỉ định XML3) XMLComplete_NVYT_KHONG_CO_TRONG_DM / _SAI_DINH_DANG (BS chỉ định XML3) | G35: 1535 | H35: Nghiệp vụ – Danh mục | I35: Phòng TCCB | J35: x
A36: 32 | B36: XML3 | C36: NGAY_KQ | D36: Gán = giờ xuất file − 3 phút, hoặc = NGAY_YL | E36: Cao | F36: XML3_INVALID_NGAY_KQ XML3_NGAY_KQ_GREATER_NGAY_RA XML3_INVALID_NGAY_KQ_LESSTHEN_NGAY_YL | G36: 2031 | H36: Kỹ thuật – Tích hợp HIS–PACS/LIS | I36: CNTT | J36: x
A37: 33 | B37: XML3 | C37: NGAY_TH_YL | D37: Gán = giờ xuất − 3 phút, hoặc = NGAY_YL | E37: Cao | F37: XML3_NGAY_TH_YL_EQUALS_NGAY_KQ XML3_EXECUTION_TIME_UNDER_3MIN | G37: 6758 | H37: Kỹ thuật – HIS | I37: CNTT | J37: x
A38: 34 | B38: XML3 | C38: PP_VO_CAM | D38: Nhóm 8, 18 (PT/TT) → "4"; nhóm khác → rỗng | E38: Nghiêm trọng | F38: XML3_INFO_ERROR_PP_VO_CAM_EMPTY | G38: 75 | H38: Nghiệp vụ – Chuyên môn lâm sàng | I38: Khoa lâm sàng | K38: Không rõ
A39: 35 | B39: XML3 | C39: NGUOI_THUC_HIEN (nhóm 1,2,3,8,18) | D39: Bỏ "CNTT"; DV khí máu 23.0103.1531 hoặc y lệnh trước 01/07/2024 → gán = MA_BAC_SI (người chỉ định); từ 01/07/2024 → "0000000000" | E39: Nghiêm trọng | F39: XMLComplete_NVYT_THIEU (người thực hiện XML3) XMLComplete_NVYT_KHONG_CO_TRONG_DM / _SAI_DINH_DANG (người thực hiện XML3) XML3_SAME_DOCTOR_ORDER_AND_EXECUTE | G39: 10186 | H39: Nghiệp vụ – Danh mục | I39: Phòng TCCB | K39: Không rõ
A40: 36 | B40: XML3 | C40: MA_BENH | D40: Giữ 13 mã đầu, luôn thêm ";" cuối chuỗi | E40: Trung bình | F40: XML3_INFO_ERROR_MA_BENH_TOO_LONG | G40: 0 | H40: Kỹ thuật – HIS | I40: CNTT | K40: Không rõ
A41: 37 | B41: XML4 | C41: GIA_TRI | D41: Cắt 47 ký tự + "..." | E41: Cao | F41: XML4_INFO_ERROR_GIA_TRI_LENGTH | G41: 1091 | H41: Kỹ thuật – Tích hợp HIS–LIS | I41: CNTT | K41: Không rõ
...

Sheet Ghi chú
A1: CÁCH ĐỌC VÀ PHÂN LOẠI
A2: • Nguồn số liệu: chạy lại bộ kiểm hiện tại (commit 63e21fa8) ở chế độ chỉ đọc trên CSDL thật ngày 16/10/2026 cho 23.967 hồ sơ BHYT ra viện 01/10–15/10/2026 (nạp lại ngày 16/10/2026) (0 hồ sơ lỗi chạy; nhóm này không có hồ sơ viện phí MA_DOITUONG_KCB = 9); mã lỗi đang tắt kiểm (is_check = 0) bị loại như khi ghi thật. Cột P sheet "Danh mục lỗi" = cùng nhóm hồ sơ khi kiểm sáng 16/10, trước khi nạp lại.
A3: • Đối chiếu: kết quả chạy lại khớp kết quả hệ thống đã ghi khi nạp (157.141 so với 157.205 cặp hồ sơ–mã lỗi; chênh lệch nhỏ do vài hồ sơ kiểm trước khi bản cập nhật quy tắc mới nhất có hiệu lực). Số trong tệp vì vậy cũng là số các đơn vị đang thấy trên màn hình Tiền giám định.
A4: • "Chặn gửi" = lỗi xuất toán (critical): hồ sơ không được xuất, ký, gửi cổng. "Không" = cảnh báo, vẫn gửi nhưng có nguy cơ bị BHXH giảm trừ.
A5: • Nhóm lớn: Nghiệp vụ = lỗi do người nhập/quy trình/danh mục; Kỹ thuật = lỗi do HIS, kết nối PACS/LIS/thiết bị, hoặc phần mềm kiểm.
A6: • Danh mục được xếp vào Nghiệp vụ vì đơn vị chủ quản danh mục (Dược, VT-TBYT, KHTH, TCKT, TCCB) phải sửa; CNTT chỉ phối hợp nạp.
A7: • Một lỗi có thể có nhiều nguyên nhân; bảng ghi nguyên nhân chính quan sát được trên dữ liệu thật, đơn vị phối hợp ghi ở cột riêng.
A8: • Thay đổi quy tắc từ bản 14/10: gộp 34 mã NVYT thành 3 mã XMLComplete_NVYT_* (thiếu / không có trong DM / sai định dạng); gộp mã + tên chỉ số trống thành XML4_CHI_SO_EMPTY; thiếu mã máy căn cứ danh mục DVKT cần mã máy (bỏ lọc theo nhóm 1/2/3); thêm quy tắc vật phẩm kèm DVKT, thời gian thực hiện dài bất thường; bỏ báo trùng giữa quy tắc cũ và mới; tắt kiểm một số mã (vd. XML2_INVALID_DON_VI_TINH). Vì kiểm lại toàn bộ nên số liệu có thể TĂNG ở mã có quy tắc mới/mở rộng.
A9: • Cột FIXERROR: số quy tắc trong tệp phân tích hệ thống khác – nơi lỗi đó bị tự sửa trên bản gửi cổng thay vì sửa tại nguồn.
A10: • Dòng chữ xám = mã lỗi chưa phát sinh trong kỳ.
